Workbook

Sheet 표지
Q1: 글자크기
A2: ( 8 )월 경영협의회 | Q2: 28 | S2: (아래를 참고해주시기 바랍니다.)
A6: ( 7 )월 실적 및 ( 8 )월 계획보고 | Q6: 18
F9: 1. | G9: 손익현황 | Q9: 14 | S9: 리스트는 다음 6개로 확정
S10: 1. 손익현황
F11: 2. | G11: 재무현황 | S11: 2. 재무현황
S12: 3. 현금흐름현황
F13: 3. | G13: 현금흐름 현황 | S13: 4. 인원현황
S14: 5. 투자현황
F15: 4. | G15: 인원현황 | S15: 6. 주요업무현황
F17: 5. | G17: 투자현황 | S17: 주요 도서 출간 현황 / 콘텐츠 작품 리스트 등은 시트명을 [별첨]으로 해주세요.
F19: 6. | G19: 주요업무현황
A23: 46248 | Q23: 14 | S23: 날짜 - 자세한 날짜
D24: =#VALUE! -> #VALUE!
A25: 주식회사 우리인터텍스 | Q25: 20 | S25: 회사명 기재
Q27: (font) 나눔바른고딕
S29: ü 페이지 레이아웃 설정 - | U29: 너비 [자동], 높이 [자동], 배율 [100%]
S30: ü 여백 설정 - | T30: 좌, 우 [1.8], 상, 하 [1.9], 머릿글, 바닥글 [0.8]
S31: ü 페이지 가운데 맞춤 - 가로 [V], 세로 [ ]
AE45: 담당 | AF45: 대표이사 | AG45: 사장

Sheet PL_26 우리
A1: 과목 | B1: 합계 | C1: 2026년 1월 | D1: 2026년 2월 | E1: 2026년 3월 | F1: 2026년 4월 | G1: 2026년 5월 | H1: 2026년 6월 | I1: 2026년 7월 | J1: 2026년 8월 | K1: 2026년 9월 | L1: 2026년 10월 | M1: 2026년 11월 | N1: 2026년 12월 | P1: 당월 | Q1: 연간누계
A2: Ⅰ.원재료비 | B2: =B3+B4-B5 -> 0 | C2: =C3+C4-C5 -> 0 | D2: =D3+D4-D5 -> 0 | E2: =E3+E4-E5 -> 0 | F2: =F3+F4-F5 -> 0 | G2: =G3+G4-G5 -> 0 | H2: =H3+H4-H5 -> 0 | I2: =I3+I4-I5 -> 0 | ... N2: =N3+N4-N5 -> 0 | P2: =N2 -> 0 | Q2: =SUM(C2:N2) -> 0 | R2: =Q2=B2 -> 1 | S2: =Q3+Q4-Q5 -> 0
A3: 기 초 원재료재고액 | B3: =SUM(C3) -> 0 | P3: =C3 -> 0 | Q3: =C3 -> 0 | R3: =Q3=B3 -> 1
A4: 당 기 원재료매입액 | B4: =SUM(C4:N4) -> 0 | P4: =N4 -> 0 | Q4: =SUM(C4:N4) -> 0 | R4: =Q4=B4 -> 1
A5: 기 말 원재료재고액 | B5: =C5 -> 0 | P5: =N5 -> 0 | Q5: =C5 -> 0 | R5: =Q5=B5 -> 1
A6: Ⅱ.부재료비 | B6: =B7+B8-B9 -> 0 | C6: =C7+C8-C9 -> 0 | D6: =D7+D8-D9 -> 0 | E6: =E7+E8-E9 -> 0 | F6: =F7+F8-F9 -> 0 | G6: =G7+G8-G9 -> 0 | H6: =H7+H8-H9 -> 0 | I6: =I7+I8-I9 -> 0 | ... N6: =N7+N8-N9 -> 0 | P6: =N6 -> 0 | Q6: =SUM(C6:N6) -> 0 | R6: =Q6=B6 -> 1
A7: 기 초 부재료재고액 | B7: =C7:C7 -> 0 | C7: 0 | D7: =C9 -> 0 | E7: =D9 -> 0 | F7: =E9 -> 0 | G7: =F9 -> 0 | H7: =G9 -> 0 | I7: =H9 -> 0 | J7: =I9 -> 0 | K7: =J9 -> 0 | ... N7: =M9 -> 0 | P7: =N7 -> 0 | Q7: =SUM(C7) -> 0 | R7: =Q7=B7 -> 1
A8: 당 기 부재료매입액 | B8: =SUM(C8:N8) -> 0 | P8: =N8 -> 0 | Q8: =SUM(C8:N8) -> 0 | R8: =Q8=B8 -> 1
A9: 기 말 부재료재고액 | B9: =N9 -> 0 | F9: 0 | P9: =N9 -> 0 | Q9: =SUM(C9:N9) -> 0 | R9: =Q9=B9 -> 1
A10: Ⅲ.노무비 | B10: =B11 -> 0 | C10: =C11 -> 0 | D10: =D11 -> 0 | E10: =E11 -> 0 | F10: =F11 -> 0 | G10: =G11 -> 0 | H10: =H11 -> 0 | I10: =I11 -> 0 | ... N10: =N11 -> 0 | P10: =N10 -> 0 | Q10: =SUM(C10:N10) -> 0 | R10: =Q10=B10 -> 1
A11: 잡 급 | B11: =SUM(C11:N11) -> 0 | P11: =N11 -> 0 | Q11: =SUM(C11:N11) -> 0 | R11: =Q11=B11 -> 1
A12: Ⅳ.경비 | B12: =SUM(B13:B19) -> 0 | C12: =SUM(C13:C19) -> 0 | D12: =SUM(D13:D19) -> 0 | E12: =SUM(E13:E19) -> 0 | F12: =SUM(F13:F19) -> 0 | G12: =SUM(G13:G19) -> 0 | H12: =SUM(H13:H19) -> 0 | I12: =SUM(I13:I19) -> 0 | ... N12: =SUM(N13:N19) -> 0 | P12: =M12 -> 0 | Q12: =SUM(C12:N12) -> 0 | R12: =Q12=B12 -> 1
A13: 복 리 후 생 비 | B13: =SUM(C13:N13) -> 0 | P13: =M13 -> 0 | Q13: =SUM(C13:N13) -> 0 | R13: =Q13=B13 -> 1
A14: 지 급 임 차 료 | B14: =SUM(C14:N14) -> 0 | P14: =M14 -> 0 | Q14: =SUM(C14:N14) -> 0 | R14: =Q14=B14 -> 1
A15: 운 반 비 | B15: =SUM(C15:N15) -> 0 | P15: =M15 -> 0 | Q15: =SUM(C15:N15) -> 0 | R15: =Q15=B15 -> 1
A16: 지 급 수 수 료 | B16: =SUM(C16:N16) -> 0 | P16: =M16 -> 0 | Q16: =SUM(C16:N16) -> 0 | R16: =Q16=B16 -> 1
A17: 외 주 가 공 비 | B17: =SUM(C17:N17) -> 0 | P17: =M17 -> 0 | Q17: =SUM(C17:N17) -> 0 | R17: =Q17=B17 -> 1
A18: 외 주 비 | B18: =SUM(C18:N18) -> 0 | P18: =M18 -> 0 | Q18: =SUM(C18:N18) -> 0 | R18: =Q18=B18 -> 1
A19: 개 발 및 그레이딩 | B19: =SUM(C19:N19) -> 0 | P19: =M19 -> 0 | Q19: =SUM(C19:N19) -> 0 | R19: =Q19=B19 -> 1
A20: Ⅴ.당기총제조비용 | B20: =SUM(C20:N20) -> 0 | C20: =C2+C6+C10+C12 -> 0 | D20: =D2+D6+D10+D12 -> 0 | E20: =E2+E6+E10+E12 -> 0 | F20: =F2+F6+F10+F12 -> 0 | G20: =G2+G6+G10+G12 -> 0 | H20: =H2+H6+H10+H12 -> 0 | I20: =I2+I6+I10+I12 -> 0 | J20: =J2+J6+J10+J12 -> 0 | ... N20: =N2+N6+N10+N12 -> 0 | P20: =M20 -> 0 | Q20: =SUM(C20:N20) -> 0 | R20: =Q20=B20 -> 1
A21: Ⅵ.기초재공품재고액 | P21: =M21 -> 0 | Q21: =SUM(C21:N21) -> 0 | R21: =Q21=B21 -> 1
A22: Ⅶ.타계정에서 대체액 | P22: =M22 -> 0 | Q22: =SUM(C22:N22) -> 0 | R22: =Q22=B22 -> 1
A23: Ⅷ.합계 | B23: =SUM(C23:N23) -> 0 | C23: =C20 -> 0 | D23: =D20 -> 0 | E23: =E20 -> 0 | F23: =F20 -> 0 | G23: =G20 -> 0 | H23: =H20 -> 0 | I23: =I20 -> 0 | J23: =J20 -> 0 | ... N23: =N20 -> 0 | P23: =M23 -> 0 | Q23: =SUM(C23:N23) -> 0 | R23: =Q23=B23 -> 1
A24: Ⅸ.기말재공품재고액 | P24: =M24 -> 0 | Q24: =SUM(C24:N24) -> 0 | R24: =Q24=B24 -> 1
A25: Ⅹ.타계정으로 대체액 | P25: =M25 -> 0 | Q25: =SUM(C25:N25) -> 0 | R25: =Q25=B25 -> 1
A26: ⅩⅠ.당기제품제조원가 | B26: =SUM(C26:N26) -> 0 | C26: =C23 -> 0 | D26: =D23 -> 0 | E26: =E23 -> 0 | F26: =F23 -> 0 | G26: =G23 -> 0 | H26: =H23 -> 0 | I26: =I23 -> 0 | J26: =J23 -> 0 | ... N26: =N23 -> 0 | P26: =M26 -> 0 | Q26: =SUM(C26:N26) -> 0 | R26: =Q26=B26 -> 1
A31: 과목 | B31: 합계 | C31: 2026년 1월 | D31: 2026년 2월 | E31: 2026년 3월 | F31: 2026년 4월 | G31: 2026년 5월 | H31: 2026년 6월 | I31: 2026년 7월 | J31: 2026년 8월 | K31: 2026년 9월 | L31: 2026년 10월 | M31: 2026년 11월 | N31: 2026년 12월 | P31: 당월 | Q31: 연간누계
A32: Ⅰ. 매 출 액 | B32: =SUM(C32:N32) -> 2209269603 | C32: =SUM(C33:C36) -> 284712111 | D32: =SUM(D33:D36) -> 507895922 | E32: =SUM(E33:E36) -> 64127445 | F32: =SUM(F33:F36) -> 455027491 | G32: =SUM(G33:G36) -> 383427327 | H32: =SUM(H33:H36) -> 380380144 | I32: =SUM(I33:I36) -> 133699163 | J32: =SUM(J33:J36) -> 0 | ... N32: =SUM(N33:N36) -> 0 | P32: =I32 -> 133699163 | Q32: =SUM(C32:N32) -> 2209269603 | R32: =Q32=B32 -> 1
A33: 상 품 매 출 | B33: =SUM(C33:N33) -> 2209269603 | C33: 284712111 | D33: 507895922 | E33: 64127445 | F33: 455027491 | G33: 383427327 | H33: 380380144 | I33: 133699163 | P33: =I33 -> 133699163 | Q33: =SUM(C33:N33) -> 2209269603 | R33: =Q33=B33 -> 1
A34: 제 품 매 출 | B34: =SUM(C34:N34) -> 0 | I34: 0 | P34: =I34 -> 0 | Q34: =SUM(C34:N34) -> 0 | R34: =Q34=B34 -> 1
A35: 수 출 매 출 | B35: =SUM(C35:N35) -> 0 | P35: =I35 -> 0
A36: 기 타 매 출 | B36: =SUM(C36:N36) -> 0 | I36: 0 | P36: =I36 -> 0 | Q36: =SUM(C36:N36) -> 0 | R36: =Q36=B36 -> 1
A37: Ⅱ. 매 출 원 가 | B37: =SUM(C37:N37) -> 1866139788 | C37: =C38+C43 -> 238215409 | D37: =D38+D43 -> 459571912 | E37: =E38+E43 -> 14847458 | F37: =F38+F43 -> 399821106 | G37: =G38+G43 -> 328467721 | H37: =H38+H43 -> 325146649 | I37: =I38+I43 -> 100069533 | J37: =J38+J43 -> 0 | ... N37: =N38+N43 -> 0 | P37: =I37 -> 100069533 | Q37: =SUM(C37:N37) -> 1866139788 | R37: =Q37=B37 -> 1
A38: 상 품 매 출 원 가 | B38: =B39+B40-B42+B41 -> 1836260319 | C38: =C39+C40-C42+C41 -> 238215409 | D38: =D39+D40-D42+D41+6543873 -> 459571912 | E38: =E39+E40-E42+E41-6543873 -> 14847458 | F38: =F39+F40-F42+F41 -> 399821106 | G38: =G39+G40-G42+G41 -> 328467721 | H38: =H39+H40-H42+H41 -> 325146649 | I38: =I39+I40-I42+I41 -> 100069533 | J38: =J39+J40-J42+J41 -> 0 | K38: =K39+K40-K42+K41 -> 0 | L38: =L39+L40-L42+L41 -> 0 | M38: =M39+M40-M42+M41 -> 0 | N38: =N39+N40-N42+N41 -> 0 | P38: =I38 -> 100069533 | Q38: =SUM(C38:N38) -> 1866139788 | R38: =Q38=B38 -> 0
A39: 기 초 상 품 재고액 | B39: =C39 -> 1089627615 | C39: 1089627615 | D39: =C42 -> 1078344448 | E39: =D42 -> 1064999154 | F39: =E42 -> 1016409141 | G39: =F42 -> 981290964 | H39: =G42 -> 946168122 | I39: =H42 -> 941063940 | K39: =J42 -> 0 | L39: =K42 -> 0 | M39: =L42 -> 0 | N39: =M42 -> 0 | P39: =I39 -> 941063940 | Q39: =SUM(C39) -> 1089627615 | R39: =Q39=B39 -> 1
A40: 당 기 상 품 매입액 | B40: =SUM(C40:N40) -> 1862789775 | C40: 238134551 | D40: 452844554 | E40: 21257604 | F40: 399702929 | G40: 328344879 | H40: 325042467 | I40: 97462791 | P40: =I40 -> 97462791 | Q40: =SUM(C40:N40) -> 1862789775 | R40: =Q40=B40 -> 1
A41: 재고자산 평가 손실 | B41: =SUM(C41:N41) -> -175093131 | C41: -11202309 | D41: -13161809 | E41: -48456286 | F41: -35000000 | G41: -35000000 | H41: -5000000 | I41: -27272727 | P41: =I41 -> -27272727 | Q41: =SUM(C41:N41) -> -175093131 | R41: =Q41=B41 -> 1
A42: 기 말 상 품 재고액 | B42: =H42 -> 941063940 | C42: 1078344448 | D42: 1064999154 | E42: 1016409141 | F42: 981290964 | G42: 946168122 | H42: 941063940 | I42: 911184471 | P42: =I42 -> 911184471 | Q42: =SUM(I42) -> 911184471 | R42: =Q42=B42 -> 0
A43: 제 품 매 출 원 가 | B43: =B44+B45-B46 -> 0 | C43: =C44+C45-C46 -> 0 | D43: =D44+D45-D46 -> 0 | E43: =E44+E45-E46 -> 0 | F43: =F44+F45-F46 -> 0 | G43: =G44+G45-G46 -> 0 | H43: =H44+H45-H46 -> 0 | I43: =I44+I45-I46 -> 0 | ... N43: =N44+N45-N46 -> 0 | P43: =I43 -> 0 | Q43: =SUM(C43:N43) -> 0 | R43: =Q43=B43 -> 1 | S43: =Q43-B43 -> 0
A44: 기 초 제 품 재고액 | B44: =C44 -> 230834232 | C44: 230834232 | D44: =C46 -> 230834232 | E44: =D46 -> 230834232 | F44: =E46 -> 230834232 | G44: =F46 -> 230834232 | H44: =G46 -> 230834232 | I44: =H46 -> 230834232 | K44: =J46 -> 0 | L44: =K46 -> 0 | M44: =L46 -> 0 | N44: =M46 -> 0 | P44: =I44 -> 230834232 | Q44: =SUM(C44) -> 230834232 | R44: =Q44=B44 -> 1
...

Sheet BS_우리인터텍스
A1: 과목 | B1: 제 28(당)기[2026/01/01 ~ 2026/07/31] | D1: 제 27(전)기[2025/01/01 ~ 2025/12/31] | H1: 과목 | I1: =B1 -> 제 28(당)기[2026/01/01 ~ 2026/07/31] | K1: =D1 -> 제 27(전)기[2025/01/01 ~ 2025/12/31]
B2: 금 액 | D2: 금 액 | I2: 금 액 | K2: 금 액
A3: 자 산 | G3: =H3=A3 -> 1 | H3: 자 산 | N3: 자 산 | P3: =H3=N3 -> 1
A4: Ⅰ. 유 동 자 산 | C4: =J4 -> 2657446277 | E4: =L4 -> 1792860915 | G4: =H4=A4 -> 1 | H4: Ⅰ. 유 동 자 산 | J4: =J5+J19 -> 2657446277 | L4: =L5+L19 -> 1792860915 | N4: Ⅰ. 유 동 자 산 | P4: =H4=N4 -> 1 | Q4: =C4=J4 -> 1
A5: (1) 당 좌 자 산 | C5: =J5 -> 2657446277 | E5: =L5 -> 1789510902 | G5: =H5=A5 -> 1 | H5: (1) 당 좌 자 산 | J5: =SUM(J6:J18,0) -> 2657446277 | L5: =SUM(L6:L18,0) -> 1789510902 | N5: (1) 당 좌 자 산 | P5: =H5=N5 -> 1 | Q5: =C5=J5 -> 1
A6: 현 금 | C6: =J6 -> 262875 | E6: =L6 -> 103005 | G6: =H6=A6 -> 1 | H6: 현 금 | J6: 262875 | L6: 103005 | N6: 현 금 | P6: =H6=N6 -> 1 | Q6: =C6=J6 -> 1
A7: 보 통 예 금 | C7: =J7 -> 560254519 | E7: =L7 -> 884266 | G7: =H7=A7 -> 1 | H7: 보 통 예 금 | J7: 560254519 | L7: 884266 | N7: 보 통 예 금 | P7: =H7=N7 -> 1 | Q7: =C7=J7 -> 1
A8: 외 화 보 통 예 금 | C8: =J8 -> 4645043 | E8: =L8 -> 45254120 | G8: =H8=A8 -> 1 | H8: 외 화 보 통 예 금 | J8: 4645043 | L8: 45254120 | N8: 외 화 보 통 예 금 | P8: =H8=N8 -> 1 | Q8: =C8=J8 -> 1
A9: 정 기 예 적 금 | C9: =J9 -> 0 | E9: =L9 -> 0 | G9: =H9=A9 -> 1 | H9: 정 기 예 적 금 | N9: 정 기 예 적 금 | P9: =H9=N9 -> 1 | Q9: =C9=J9 -> 1
A10: 외 상 매 출 금 | C10: =J10 -> 2079944752 | E10: =L10 -> 1720894049 | G10: =H10=A10 -> 1 | H10: 외 상 매 출 금 | J10: 2079944752 | L10: 1720894049 | N10: 외 상 매 출 금 | P10: =H10=N10 -> 1 | Q10: =C10=J10 -> 1
A11: 단 기 대 여 금 | C11: =J11 -> 0 | E11: =L11 -> 0 | G11: =H11=A11 -> 1 | H11: 단 기 대 여 금 | J11: 0 | L11: 0 | N11: 단 기 대 여 금 | P11: =H11=N11 -> 1 | Q11: =C11=J11 -> 1
A12: 미 수 수 익 | C12: =J12 -> 0 | E12: =L12 -> 0 | G12: =H12=A12 -> 1 | H12: 미 수 수 익 | J12: 0 | L12: 0 | N12: 미 수 수 익 | P12: =H12=N12 -> 1 | Q12: =C12=J12 -> 1
A13: 미 수 금 | C13: =J13 -> 44817 | E13: =L13 -> 44817 | G13: =H13=A13 -> 1 | H13: 미 수 금 | J13: 44817 | L13: 44817 | N13: 미 수 금 | P13: =H13=N13 -> 1 | Q13: =C13=J13 -> 1
A14: 계 약 금 | C14: =J14 -> 0 | E14: =L14 -> 0 | G14: =H14=A14 -> 1 | H14: 계 약 금 | N14: 계 약 금 | P14: =H14=N14 -> 1 | Q14: =C14=J14 -> 1
A15: 선 급 금 | C15: =J15 -> 0 | E15: =L15 -> 17481100 | G15: =H15=A15 -> 1 | H15: 선 급 금 | L15: 17481100 | N15: 선 급 금 | P15: =H15=N15 -> 1 | Q15: =C15=J15 -> 1
A16: 선 급 비 용 | C16: =J16 -> 1997785 | E16: =L16 -> 1323425 | G16: =H16=A16 -> 1 | H16: 선 급 비 용 | J16: 1997785 | L16: 1323425 | N16: 선 급 비 용 | P16: =H16=N16 -> 1 | Q16: =C16=J16 -> 1
A17: 부 가 세 대 급 금 | C17: =J17 -> 10285956 | E17: =L17 -> 0 | G17: =H17=A17 -> 1 | H17: 부 가 세 대 급 금 | J17: 10285956 | L17: 0 | N17: 부 가 세 대 급 금 | P17: =H17=N17 -> 1 | Q17: =C17=J17 -> 1
A18: 선 납 세 금 | C18: =J18 -> 10530 | E18: =L18 -> 3526120 | G18: =H18=A18 -> 1 | H18: 선 납 세 금 | J18: 10530 | L18: 3526120 | N18: 선 납 세 금 | P18: =H18=N18 -> 1 | Q18: =C18=J18 -> 1
A19: (2) 재 고 자 산 | C19: =J19 -> 0 | E19: =L19 -> 3350013 | G19: =H19=A19 -> 1 | H19: (2) 재 고 자 산 | J19: =SUM(J20:J22,0) -> 0 | L19: =SUM(L20:L22,0) -> 3350013 | N19: (2) 재 고 자 산 | P19: =H19=N19 -> 1 | Q19: =C19=J19 -> 1
A20: 상 품 | C20: =J20 -> 0 | E20: =L20 -> 3350013 | G20: =H20=A20 -> 1 | H20: 상 품 | L20: 3350013 | N20: 상 품 | P20: =H20=N20 -> 1 | Q20: =C20=J20 -> 1
A21: 제 품 | C21: =J21 -> 0 | E21: =L21 -> 0 | G21: =H21=A21 -> 1 | H21: 제 품 | L21: 0 | N21: 제 품 | P21: =H21=N21 -> 1 | Q21: =C21=J21 -> 1
A22: 원 재 료 | C22: =J22 -> 0 | E22: =L22 -> 0 | G22: =H22=A22 -> 1 | H22: 원 재 료 | N22: 원 재 료 | P22: =H22=N22 -> 1 | Q22: =C22=J22 -> 1
A23: 부 재 료 | C23: =J23 -> 0 | E23: =L23 -> 0 | G23: =H23=A23 -> 1 | H23: 부 재 료 | N23: 부 재 료 | P23: =H23=N23 -> 1 | Q23: =C23=J23 -> 1
A24: Ⅱ. 비 유 동 자 산 | C24: =J24 -> 21839373782 | E24: =L24 -> 22923655684 | G24: =H24=A24 -> 1 | H24: Ⅱ. 비 유 동 자 산 | J24: =J25+J29+J38+J41 -> 21839373782 | L24: =L25+L29+L38+L41 -> 22923655684 | N24: Ⅱ. 비 유 동 자 산 | P24: =H24=N24 -> 1 | Q24: =C24=J24 -> 1
A25: (1) 투 자 자 산 | C25: =J25 -> 20350490411 | E25: =L25 -> 20350490411 | G25: =H25=A25 -> 1 | H25: (1) 투 자 자 산 | J25: =SUM(J26:J28,0) -> 20350490411 | L25: =SUM(L26:L28,0) -> 20350490411 | N25: (1) 투 자 자 산 | P25: =H25=N25 -> 1 | Q25: =C25=J25 -> 1
A26: 매 도 가 능 증 권 | C26: =J26 -> 109910000 | E26: =L26 -> 109910000 | G26: =H26=A26 -> 1 | H26: 매 도 가 능 증 권 | J26: 109910000 | L26: 109910000 | N26: 매 도 가 능 증 권 | P26: =H26=N26 -> 1 | Q26: =C26=J26 -> 1
A27: 지 분 법 적 용 투자주식 | C27: =J27 -> 20237914013 | E27: =L27 -> 20237914013 | G27: =H27=A27 -> 1 | H27: 지 분 법 적 용 투자주식 | J27: 20237914013 | L27: 20237914013 | N27: 지 분 법 적 용 투자주식 | P27: =H27=N27 -> 1 | Q27: =C27=J27 -> 1
A28: 퇴 직 보 험 예 치 금 | C28: =J28 -> 2666398 | E28: =L28 -> 2666398 | G28: =H28=A28 -> 1 | H28: 퇴 직 보 험 예 치 금 | J28: 2666398 | L28: 2666398 | N28: 퇴 직 보 험 예 치 금 | P28: =H28=N28 -> 1 | Q28: =C28=J28 -> 1
A29: (2) 유 형 자 산 | C29: =J29 -> 5180584 | E29: =L29 -> 7288494 | G29: =H29=A29 -> 1 | H29: (2) 유 형 자 산 | J29: =SUM(J30:J37) -> 5180584 | L29: =SUM(L30:L37) -> 7288494 | N29: (2) 유 형 자 산 | P29: =H29=N29 -> 1 | Q29: =C29=J29 -> 1
A30: 기 계 장 치 | B30: =I30 -> 86822518 | C30: =J30 -> 0 | D30: =K30 -> 86822518 | E30: =L30 -> 0 | G30: =H30=A30 -> 1 | H30: 기 계 장 치 | I30: 86822518 | K30: 86822518 | N30: 기 계 장 치 | P30: =H30=N30 -> 1 | Q30: =C30=J30 -> 1
A31: 감 가 상 각 누 계 액 | B31: =I31 -> 86816518 | C31: =J31 -> 6000 | D31: =K31 -> 86816518 | E31: =L31 -> 6000 | G31: =H31=A31 -> 1 | H31: 감 가 상 각 누 계 액 | I31: 86816518 | J31: =I30-I31 -> 6000 | K31: 86816518 | L31: =K30-K31 -> 6000 | N31: 감 가 상 각 누 계 액 | P31: =H31=N31 -> 1 | Q31: =C31=J31 -> 1
A32: 차 량 운 반 구 | B32: =I32 -> 110968776 | C32: =J32 -> 0 | D32: =K32 -> 110968776 | E32: =L32 -> 0 | G32: =H32=A32 -> 1 | H32: 차 량 운 반 구 | I32: 110968776 | K32: 110968776 | N32: 차 량 운 반 구 | P32: =H32=N32 -> 1 | Q32: =C32=J32 -> 1
A33: 감 가 상 각 누 계 액 | B33: =I33 -> 105840560 | C33: =J33 -> 5128216 | D33: =K33 -> 103732650 | E33: =L33 -> 7236126 | G33: =H33=A33 -> 1 | H33: 감 가 상 각 누 계 액 | I33: 105840560 | J33: =I32-I33 -> 5128216 | K33: 103732650 | L33: =K32-K33 -> 7236126 | N33: 감 가 상 각 누 계 액 | P33: =H33=N33 -> 1 | Q33: =C33=J33 -> 1
A34: 비 품 | B34: =I34 -> 47994865 | C34: =J34 -> 0 | D34: =K34 -> 47994865 | E34: =L34 -> 0 | G34: =H34=A34 -> 1 | H34: 비 품 | I34: 47994865 | K34: 47994865 | N34: 비 품 | P34: =H34=N34 -> 1 | Q34: =C34=J34 -> 1
A35: 감 가 상 각 누 계 액 | B35: =I35 -> 47953865 | C35: =J35 -> 41000 | D35: =K35 -> 47953865 | E35: =L35 -> 41000 | G35: =H35=A35 -> 1 | H35: 감 가 상 각 누 계 액 | I35: 47953865 | J35: =I34-I35 -> 41000 | K35: 47953865 | L35: =K34-K35 -> 41000 | N35: 감 가 상 각 누 계 액 | P35: =H35=N35 -> 1 | Q35: =C35=J35 -> 1
A36: 시 설 장 치 | B36: =I36 -> 37906280 | C36: =J36 -> 0 | D36: =K36 -> 37906280 | E36: =L36 -> 0 | G36: =H36=A36 -> 1 | H36: 시 설 장 치 | I36: 37906280 | K36: 37906280 | N36: 시 설 장 치 | P36: =H36=N36 -> 1 | Q36: =C36=J36 -> 1
A37: 감 가 상 각 누 계 액 | B37: =I37 -> 37900912 | C37: =J37 -> 5368 | D37: =K37 -> 37900912 | E37: =L37 -> 5368 | G37: =H37=A37 -> 1 | H37: 감 가 상 각 누 계 액 | I37: 37900912 | J37: =I36-I37 -> 5368 | K37: 37900912 | L37: =K36-K37 -> 5368 | N37: 감 가 상 각 누 계 액 | P37: =H37=N37 -> 1 | Q37: =C37=J37 -> 1
A38: (3) 무 형 자 산 | C38: =J38 -> 1350000 | E38: =L38 -> 1350000 | G38: =H38=A38 -> 1 | H38: (3) 무 형 자 산 | J38: =SUM(J39:J40,0) -> 1350000 | L38: =SUM(L39:L40,0) -> 1350000 | N38: (3) 무 형 자 산 | P38: =H38=N38 -> 1 | Q38: =C38=J38 -> 1
A39: 특 허 권 | C39: =J39 -> 1350000 | E39: =L39 -> 1350000 | G39: =H39=A39 -> 1 | H39: 특 허 권 | J39: 1350000 | L39: 1350000 | N39: 특 허 권 | P39: =H39=N39 -> 1 | Q39: =C39=J39 -> 1
A40: 개 발 비 | C40: =J40 -> 0 | E40: =L40 -> 0 | G40: =H40=A40 -> 1 | H40: 개 발 비 | J40: 0 | L40: 0 | N40: 개 발 비 | P40: =H40=N40 -> 1 | Q40: =C40=J40 -> 1
...

Sheet 손익 현황_우리
B1: 1. 손익 현황
U3: (단위:백만원) | V3: (단위:백만원)
B4: 구분 | C4: (7월) 손익 실적 | K4: (8월) 손익 예상 | O4: 2026년 연간 누계실적 (~7월)
C5: 전년동기 실적 | E5: 사업계획 | G5: 당월실적 | I5: 전년동기 대비 | J5: 사업계획 대비 | K5: 전년동기 실적 | M5: 예상실적 | O5: 전년동기 실적 | Q5: 사업계획 | S5: 연간실적 | U5: 전년동기 대비 | V5: 사업계획 대비 | AC5: 달라지는 점
B6: 제품매출 | C6: =('PL_25 우리'!P34)/1000000 -> 174.06877 | D6: =IFERROR(C6/C$11,"-") -> 0.46607154 | F6: =IFERROR(E6/E$11,"-") -> - | G6: =('PL_26 우리'!P34)/1000000 -> 0 | H6: =IFERROR(G6/G$11,"-") -> 0 | I6: =IFERROR(IF(AND((G6+G7+G10)<0,(C6+C7+C10)<0),-((G6+G7+G10)-(C6+C7+C10))/(C6+C7+C10),IF(AND((G6+G7+G10)<0,C6>0),((G6+G7+G10)-(C6+C7+C10))/(C6+C7+C10),IF(AND((G6+G7+G10)>0,(C6+C7+C10)<0),-((G6+G7+G10)-(C6+C7+C10))/(C6+C7+C10),IF(ISERROR((G6+G7+G10)/(C6+C7+C10)),"-",((G6+G7+G10)-(C6+C7+C10))/(C6+C7+C10))))),"-") -> -0.64201865 | J6: =IFERROR(IF(AND((G6+G7)<0,E6<0),-((G6+G7)-E6)/E6,IF(AND((G6+G7)<0,E6>0),((G6+G7)-E6)/E6,IF(AND((G6+G7)>0,E6<0),-((G6+G7)-E6)/E6,IF(ISERROR((G6+G7)/E6),"-",((G6+G7)-E6)/E6)))),"-") -> - | K6: ='PL_25 우리'!Q34/1000000 -> 287.02547 | L6: =IFERROR(K6/K$11,"-") -> 0.77879714 | M6: 0 | N6: =IFERROR(M6/M$11,"-") -> 0 | O6: =('PL_25 우리'!R34)/1000000 -> 994.22838 | P6: =IFERROR(O6/O$11,"-") -> 0.3566946 | R6: =IFERROR(Q6/Q$11,"-") -> - | S6: =('PL_26 우리'!Q34)/1000000 -> 0 | T6: =IFERROR(S6/S$11,"-") -> 0 | U6: =IFERROR(IF(AND((S6+S7+S10)<0,(O6+O7+O10)<0),-((S6+S7+S10)-(O6+O7+O10))/(O6+O7+O10),IF(AND((S6+S7+S10)<0,O6>0),((S6+S7+S10)-(O6+O7+O10))/(O6+O7+O10),IF(AND((S6+S7+S10)>0,(O6+O7+O10)<0),-((S6+S7+S10)-(O6+O7+O10))/(O6+O7+O10),IF(ISERROR((S6+S7+S10)/(O6+O7+O10)),"-",((S6+S7+S10)-(O6+O7+O10))/(O6+O7+O10))))),"-") -> -0.20739081 | V6: =IFERROR(IF(AND((S6+S7)<0,Q6<0),-((S6+S7)-Q6)/Q6,IF(AND((S6+S7)<0,Q6>0),((S6+S7)-Q6)/Q6,IF(AND((S6+S7)>0,Q6<0),-((S6+S7)-Q6)/Q6,IF(ISERROR((S6+S7)/Q6),"-",((S6+S7)-Q6)/Q6)))),"-") -> - | Y6: =(G6+G7)/(C6+C7)-1 -> -0.64201865 | Z6: =(S6+S7)/(O6+O7)-1 -> -0.20739081 | AC6: 쌤앤파커스
B7: 상품매출 | C7: =('PL_25 우리'!P33)/1000000 -> 199.41203 | D7: =IFERROR(C7/C$11,"-") -> 0.53392846 | G7: =+'PL_26 우리'!P33/1000000 -> 133.69916 | H7: =IFERROR(G7/G$11,"-") -> 1 | K7: ='PL_25 우리'!Q33/1000000 -> 81.524251 | L7: =IFERROR(K7/K$11,"-") -> 0.22120286 | M7: =146 -> 146 | N7: =IFERROR(M7/M$11,"-") -> 1 | O7: =('PL_25 우리'!R33)/1000000 -> 1793.1095 | P7: =IFERROR(O7/O$11,"-") -> 0.6433054 | S7: =('PL_26 우리'!Q33)/1000000 -> 2209.2696 | T7: =IFERROR(S7/S$11,"-") -> 1
B8: 수출매출 | AC8: 2016년 | AD8: 2017년 | AE8: 달라지는 점
B9: (EM/EL 수출실적)
B10: 기타매출 | C10: ='PL_25 우리'!P36/1000000 -> 0 | D10: =IFERROR(C10/C$11,"-") -> 0 | F10: =IFERROR(E10/E$11,"-") -> - | G10: =('PL_26 우리'!P36)/1000000 -> 0 | H10: =IFERROR(G10/G$11,"-") -> 0 | J10: =IFERROR(IF(AND(G10<0,E10<0),-(G10-E10)/E10,IF(AND(G10<0,E10>0),(G10-E10)/E10,IF(AND(G10>0,E10<0),-(G10-E10)/E10,IF(ISERROR(G10/E10),"-",(G10-E10)/E10)))),"-") -> - | K10: ='PL_25 우리'!Q36/1000000 -> 0 | L10: =IFERROR(K10/K$11,"-") -> 0 | N10: =IFERROR(M10/M$11,"-") -> 0 | O10: ='PL_25 우리'!R36/1000000 -> 0 | P10: =IFERROR(O10/O$11,"-") -> 0 | R10: =IFERROR(Q10/Q$11,"-") -> - | S10: =('PL_26 우리'!Q36)/1000000 -> 0 | T10: =IFERROR(S10/S$11,"-") -> 0 | V10: =IFERROR(IF(AND(S10<0,Q10<0),-(S10-Q10)/Q10,IF(AND(S10<0,Q10>0),(S10-Q10)/Q10,IF(AND(S10>0,Q10<0),-(S10-Q10)/Q10,IF(ISERROR(S10/Q10),"-",(S10-Q10)/Q10)))),"-") -> - | AD10: 인세 | AE10: 일반관리비에 있던 인세 매출원가에 포함
B11: 매출액 | C11: =SUM(C6:C10) -> 373.48081 | D11: =IFERROR(C11/C$11,"-") -> 1 | E11: =SUM(E6:E10)-E9 -> 0 | F11: =IFERROR(E11/E$11,"-") -> - | G11: =SUM(G6:G10)-G9 -> 133.69916 | H11: =IFERROR(G11/G$11,"-") -> 1 | I11: =IF(C11<0,(G11-C11)/ABS(C11),(G11-C11)/C11) -> -0.64201865 | J11: =IFERROR(IF(AND(G11<0,E11<0),-(G11-E11)/E11,IF(AND(G11<0,E11>0),(G11-E11)/E11,IF(AND(G11>0,E11<0),-(G11-E11)/E11,IF(ISERROR(G11/E11),"-",(G11-E11)/E11)))),"-") -> - | K11: =SUM(K6:K10)-K9 -> 368.54972 | L11: =IFERROR(K11/K$11,"-") -> 1 | M11: =SUM(M6:M10)-M9 -> 146 | N11: =IFERROR(M11/M$11,"-") -> 1 | O11: =SUM(O6:O10) -> 2787.3379 | P11: =IFERROR(O11/O$11,"-") -> 1 | Q11: =SUM(Q6:Q10)-Q9 -> 0 | R11: =IFERROR(Q11/Q$11,"-") -> - | S11: =SUM(S6:S10)-S9 -> 2209.2696 | T11: =IFERROR(S11/S$11,"-") -> 1 | U11: =IF(O11<0,(S11-O11)/ABS(O11),(S11-O11)/O11) -> -0.20739081 | V11: =IFERROR(IF(AND(S11<0,Q11<0),-(S11-Q11)/Q11,IF(AND(S11<0,Q11>0),(S11-Q11)/Q11,IF(AND(S11>0,Q11<0),-(S11-Q11)/Q11,IF(ISERROR(S11/Q11),"-",(S11-Q11)/Q11)))),"-") -> - | Y11: =(G11)/(C11)-1 -> -0.64201865 | Z11: =(S11)/(O11)-1 -> -0.20739081 | AC11: 재료비 | AD11: 재료비
B12: 원재료 | C12: =('PL_25 우리'!P42)/1000000 -> 169.49027 | D12: =IFERROR($C12/($C$8+$C$6),"-") -> 0.97369715 | F12: =IFERROR($E12/($E$8+$E$6),"-") -> - | G12: =('PL_26 우리'!P43)/1000000-G14 -> 0 | H12: =IFERROR($G12/($G$8+$G$6),"-") -> - | I12: =IFERROR(IF(AND(G12<0,C12<0),-(G12-C12)/C12,IF(AND(G12<0,C12>0),(G12-C12)/C12,IF(AND(G12>0,C12<0),-(G12-C12)/C12,IF(ISERROR(G12/C12),"-",(G12-C12)/C12)))),"-") -> -1 | J12: =IFERROR(IF(AND(G12<0,E12<0),-(G12-E12)/E12,IF(AND(G12<0,E12>0),(G12-E12)/E12,IF(AND(G12>0,E12<0),-(G12-E12)/E12,IF(ISERROR(G12/E12),"-",(G12-E12)/E12)))),"-") -> - | K12: =('PL_25 우리'!Q42)/1000000 -> 279.32456 | L12: =IFERROR($K12/($K$8+$K$6),"-") -> 0.97316994 | M12: =+(0*98.5%) -> 0 | N12: =IFERROR(M12/M$6,"-") -> - | O12: =('PL_25 우리'!R42)/1000000 -> 905.79068 | P12: =IFERROR($O12/($O$8+$O$6),"-") -> 0.91104891 | R12: =IFERROR($Q12/($Q$8+$Q$6),"-") -> - | S12: =(('PL_26 우리'!Q43)/1000000)-S14 -> 0 | T12: =IFERROR($S12/($S$8+$S$6),"-") -> - | U12: =IFERROR(IF(AND(S12<0,O12<0),-(S12-O12)/O12,IF(AND(S12<0,O12>0),(S12-O12)/O12,IF(AND(S12>0,O12<0),-(S12-O12)/O12,IF(ISERROR(S12/O12),"-",(S12-O12)/O12)))),"-") -> -1 | V12: =IFERROR(IF(AND(S12<0,Q12<0),-(S12-Q12)/Q12,IF(AND(S12<0,Q12>0),(S12-Q12)/Q12,IF(AND(S12>0,Q12<0),-(S12-Q12)/Q12,IF(ISERROR(S12/Q12),"-",(S12-Q12)/Q12)))),"-") -> - | Y12: 재료비 | Z12: 재료비 | AA12: 재료비 | AC12: 노무비 | AD12: 노무비
B13: 외주가공비 | C13: 0 | E13: 0 | F13: =IFERROR($C13/($C$8+$C$6),"-") -> 0 | G13: =('PL_26 우리'!P17)/1000000 -> 0 | H13: =IFERROR($C13/($C$8+$C$6),"-") -> 0 | I13: =IFERROR(IF(AND(G13<0,C13<0),-(G13-C13)/C13,IF(AND(G13<0,C13>0),(G13-C13)/C13,IF(AND(G13>0,C13<0),-(G13-C13)/C13,IF(ISERROR(G13/C13),"-",(G13-C13)/C13)))),"-") -> - | J13: =IFERROR(IF(AND(G13<0,E13<0),-(G13-E13)/E13,IF(AND(G13<0,E13>0),(G13-E13)/E13,IF(AND(G13>0,E13<0),-(G13-E13)/E13,IF(ISERROR(G13/E13),"-",(G13-E13)/E13)))),"-") -> - | K13: 0 | L13: =IFERROR($C13/($C$8+$C$6),"-") -> 0 | M13: 0 | N13: =IFERROR($M13/($M$8+$M$6),"-") -> - | O13: 0 | P13: =IFERROR($C13/($C$8+$C$6),"-") -> 0 | Q13: 0 | R13: =IFERROR($C13/($C$8+$C$6),"-") -> 0 | S13: ='PL_25 우리'!R17/1000000 -> 0 | T13: =IFERROR($C13/($C$8+$C$6),"-") -> 0 | U13: =IFERROR(IF(AND(S13<0,O13<0),-(S13-O13)/O13,IF(AND(S13<0,O13>0),(S13-O13)/O13,IF(AND(S13>0,O13<0),-(S13-O13)/O13,IF(ISERROR(S13/O13),"-",(S13-O13)/O13)))),"-") -> - | V13: =IFERROR(IF(AND(S13<0,Q13<0),-(S13-Q13)/Q13,IF(AND(S13<0,Q13>0),(S13-Q13)/Q13,IF(AND(S13>0,Q13<0),-(S13-Q13)/Q13,IF(ISERROR(S13/Q13),"-",(S13-Q13)/Q13)))),"-") -> -
B14: 기타경비 | C14: 0 | D14: =IFERROR($C14/($C$8+$C$6+$C$10),"-") -> 0 | E14: 0 | F14: =IFERROR($E14/($E$8+$E$6),"-") -> - | G14: =('PL_26 우리'!P12+'PL_26 우리'!P10+'PL_26 우리'!P6)/1000000 -> 0 | H14: =IFERROR($G14/($G$8+$G$6),"-") -> - | I14: =IFERROR(IF(AND(G14<0,C14<0),-(G14-C14)/C14,IF(AND(G14<0,C14>0),(G14-C14)/C14,IF(AND(G14>0,C14<0),-(G14-C14)/C14,IF(ISERROR(G14/C14),"-",(G14-C14)/C14)))),"-") -> - | J14: =IFERROR(IF(AND(G14<0,E14<0),-(G14-E14)/E14,IF(AND(G14<0,E14>0),(G14-E14)/E14,IF(AND(G14>0,E14<0),-(G14-E14)/E14,IF(ISERROR(G14/E14),"-",(G14-E14)/E14)))),"-") -> - | K14: 0 | L14: =IFERROR($K14/($K$8+$K$6),"-") -> 0 | N14: =IFERROR($M14/($M$8+$M$6),"-") -> - | O14: 0 | P14: =IFERROR($O14/($O$8+$O$6),"-") -> 0 | Q14: 0 | R14: =IFERROR($Q14/($Q$8+$Q$6),"-") -> - | S14: =('PL_26 우리'!Q6+'PL_26 우리'!Q12)/1000000 -> 0 | T14: =IFERROR($S14/($S$8+$S$6),"-") -> - | U14: =IFERROR(IF(AND(S14<0,O14<0),-(S14-O14)/O14,IF(AND(S14<0,O14>0),(S14-O14)/O14,IF(AND(S14>0,O14<0),-(S14-O14)/O14,IF(ISERROR(S14/O14),"-",(S14-O14)/O14)))),"-") -> - | V14: =IFERROR(IF(AND(S14<0,Q14<0),-(S14-Q14)/Q14,IF(AND(S14<0,Q14>0),(S14-Q14)/Q14,IF(AND(S14>0,Q14<0),-(S14-Q14)/Q14,IF(ISERROR(S14/Q14),"-",(S14-Q14)/Q14)))),"-") -> - | Y14: 외주가공비 | Z14: 무형자산상각비 | AA14: 외주가공비 | AD14: 기타경비
B15: 제품매출원가 | C15: =SUM(C12:C14) -> 169.49027 | D15: =IFERROR($C15/($C$8+$C$6+C10),"-") -> 0.97369715 | E15: =SUM(E12:E14) -> 0 | F15: =IFERROR($E15/($E$8+$E$6),"-") -> - | G15: =SUM(G12:G14) -> 0 | H15: =IFERROR($G15/($G$8+$G$6),"-") -> - | I15: =IFERROR(IF(AND((G15+G16)<0,(C15+C16)<0),-((G15+G16)-(C15+C16))/(C15+C16),IF(AND((G15+G16)<0,C15>0),((G15+G16)-(C15+C16))/(C15+C16),IF(AND((G15+G16)>0,(C15+C16)<0),-((G15+G16)-(C15+C16))/(C15+C16),IF(ISERROR((G15+G16)/(C15+C16)),"-",((G15+G16)-(C15+C16))/(C15+C16))))),"-") -> -0.72256416 | J15: =IFERROR(IF(AND((G15+G16)<0,E15<0),-((G15+G16)-E15)/E15,IF(AND((G15+G16)<0,E15>0),((G15+G16)-E15)/E15,IF(AND((G15+G16)>0,E15<0),-((G15+G16)-E15)/E15,IF(ISERROR((G15+G16)/E15),"-",((G15+G16)-E15)/E15)))),"-") -> - | K15: =SUM(K12:K14) -> 279.32456 | L15: =IFERROR($K15/($K$8+$K$6),"-") -> 0.97316994 | M15: =SUM(M12:M14) -> 0 | N15: =IFERROR($M15/($M$8+$M$6),"-") -> - | O15: =SUM(O12:O14) -> 905.79068 | P15: =IFERROR(($O15+$O16)/($O$7+$O$6+$O$10),"-") -> 0.97798637 | Q15: =SUM(Q12:Q14) -> 0 | R15: =IFERROR($C15/($C$8+$C$6),"-") -> 0.97369715 | S15: =SUM(S12:S14) -> 0 | T15: =IFERROR($S15/($S$8+$S$6),"-") -> - | U15: =IFERROR(IF(AND((S15+S16)<0,(O15+O16)<0),-((S15+S16)-(O15+O16))/(O15+O16),IF(AND((S15+S16)<0,O15>0),((S15+S16)-(O15+O16))/(O15+O16),IF(AND((S15+S16)>0,(O15+O16)<0),-((S15+S16)-(O15+O16))/(O15+O16),IF(ISERROR((S15+S16)/(O15+O16)),"-",((S15+S16)-(O15+O16))/(O15+O16))))),"-") -> -0.292916 | V15: =IFERROR(IF(AND((S15+S16)<0,Q15<0),-((S15+S16)-Q15)/Q15,IF(AND((S15+S16)<0,Q15>0),((S15+S16)-Q15)/Q15,IF(AND((S15+S16)>0,Q15<0),-((S15+S16)-Q15)/Q15,IF(ISERROR((S15+S16)/Q15),"-",((S15+S16)-Q15)/Q15)))),"-") -> - | Y15: =(G15+G16)/(C15+C16)-1 -> -0.72256416 | Z15: =(S15+S16)/(O15+O16)-1 -> -0.292916 | AC15: 2016년 | AD15: 2017년 | AE15: 달라지는 점
B16: 상품매출원가 | C16: =(+'PL_25 우리'!P38+'PL_25 우리'!P66+'PL_25 우리'!P65)/1000000 -> 191.20405 | D16: =IFERROR(C16/C$7,"-") -> 0.95883909 | G16: =('PL_26 우리'!P38+'PL_26 우리'!P67+'PL_26 우리'!P66)/1000000 -> 100.06953 | H16: =IFERROR(G16/G$7,"-") -> 0.74846791 | K16: =(+'PL_25 우리'!Q38+'PL_25 우리'!Q66+'PL_25 우리'!Q65)/1000000 -> 79.506097 | L16: =IFERROR($K16/($K$8+$K$7),"-") -> 0.97524474 | M16: 145 | N16: =IFERROR(M16/M$7,"-") -> 0.99315068 | O16: =(+'PL_25 우리'!R38)/1000000 -> 1820.1878 | S16: =(+'PL_26 우리'!Q38+'PL_26 우리'!Q67+'PL_26 우리'!Q66)/1000000 -> 1927.4957 | T16: =IFERROR(S16/S$7,"-") -> 0.87245836 | AC16: 재료비 | AD16: 인세 | AE16: 순서만 바꿈
B17: 매출원가 | C17: =SUM(C15:C16) -> 360.69432 | D17: =IFERROR(C17/C$11,"-") -> 0.96576401 | E17: =SUM(E15:E16) -> 0 | F17: =IFERROR(E17/E$11,"-") -> - | G17: =SUM(G15:G16) -> 100.06953 | H17: =IFERROR(G17/G$11,"-") -> 0.74846791 | I17: =IF(C17<0,(G17-C17)/ABS(C17),(G17-C17)/C17) -> -0.72256416 | J17: =IFERROR(IF(AND(G17<0,E17<0),-(G17-E17)/E17,IF(AND(G17<0,E17>0),(G17-E17)/E17,IF(AND(G17>0,E17<0),-(G17-E17)/E17,IF(ISERROR(G17/E17),"-",(G17-E17)/E17)))),"-") -> - | K17: =SUM(K15:K16) -> 358.83065 | L17: =IFERROR(K17/K$11,"-") -> 0.97362889 | M17: =SUM(M15:M16) -> 145 | N17: =IFERROR(M17/M$11,"-") -> 0.99315068 | O17: =SUM(O15:O16) -> 2725.9784 | P17: =IFERROR(O17/O$11,"-") -> 0.97798637 | Q17: =SUM(Q15:Q16) -> 0 | R17: =IFERROR(Q17/Q$11,"-") -> - | S17: =SUM(S15:S16) -> 1927.4957 | T17: =IFERROR(S17/S$11,"-") -> 0.87245836 | U17: =IF(O17<0,(S17-O17)/ABS(O17),(S17-O17)/O17) -> -0.292916 | V17: =IFERROR(IF(AND(S17<0,Q17<0),-(S17-Q17)/Q17,IF(AND(S17<0,Q17>0),(S17-Q17)/Q17,IF(AND(S17>0,Q17<0),-(S17-Q17)/Q17,IF(ISERROR(S17/Q17),"-",(S17-Q17)/Q17)))),"-") -> - | Y17: =(G17)/(C17)-1 -> -0.72256416 | Z17: =(S17)/(O17)-1 -> -0.292916
B18: 매출총이익 | C18: =C11-C17 -> 12.786486 | D18: =IFERROR(C18/C$11,"-") -> 0.034235992 | E18: =E11-E17 -> 0 | F18: =IFERROR(E18/E$11,"-") -> - | G18: =G11-G17 -> 33.62963 | H18: =IFERROR(G18/G$11,"-") -> 0.25153209 | I18: =IFERROR(IF(ROUND(C18,0)<0, (ROUND(G18,0)-ROUND(C18,0))/ABS(ROUND(C18,0)), (ROUND(G18,0)-ROUND(C18,0))/ROUND(C18,0)), "-") -> 1.6153846 | J18: =IFERROR(IF(AND(G18<0,E18<0),-(G18-E18)/E18,IF(AND(G18<0,E18>0),(G18-E18)/E18,IF(AND(G18>0,E18<0),-(G18-E18)/E18,IF(ISERROR(G18/E18),"-",(G18-E18)/E18)))),"-") -> - | K18: =K11-K17 -> 9.719066 | L18: =IFERROR(K18/K$11,"-") -> 0.026371112 | M18: =M11-M17 -> 1 | N18: =IFERROR(M18/M$11,"-") -> 0.0068493151 | O18: =O11-O17 -> 61.359436 | P18: =IFERROR(O18/O$11,"-") -> 0.022013634 | Q18: =Q11-Q17 -> 0 | R18: =IFERROR(Q18/Q$11,"-") -> - | S18: =S11-S17 -> 281.77388 | T18: =IFERROR(S18/S$11,"-") -> 0.12754164 | U18: =IFERROR(IF(ROUND(O18,0)<0, (ROUND(S18,0)-ROUND(O18,0))/ABS(ROUND(O18,0)), (ROUND(S18,0)-ROUND(O18,0))/ROUND(O18,0)), "-") -> 3.6229508 | V18: =IFERROR(IF(AND(S18<0,Q18<0),-(S18-Q18)/Q18,IF(AND(S18<0,Q18>0),(S18-Q18)/Q18,IF(AND(S18>0,Q18<0),-(S18-Q18)/Q18,IF(ISERROR(S18/Q18),"-",(S18-Q18)/Q18)))),"-") -> - | Y18: =(G18)/(C18)-1 -> 1.6300916 | Z18: =(S18)/(O18)-1 -> 3.592185 | AC18: 노무비 | AD18: 재료비
B19: 직접 인건비 | C19: ='PL_25 우리'!P89/1000000-C20 -> 14.766823 | D19: =IFERROR(C19/C$11,"-") -> 0.039538372 | F19: =IFERROR(E19/E$11,"-") -> - | G19: ='PL_26 우리'!P91/1000000-G20 -> 5.872087 | H19: =IFERROR(G19/G$11,"-") -> 0.043920148 | I19: =IFERROR(IF(ROUND(C19,0)<0, (ROUND(G19,0)-ROUND(C19,0))/ABS(ROUND(C19,0)), (ROUND(G19,0)-ROUND(C19,0))/ROUND(C19,0)), "-") -> -0.6 | J19: =IFERROR(IF(AND(G19<0,E19<0),-(G19-E19)/E19,IF(AND(G19<0,E19>0),(G19-E19)/E19,IF(AND(G19>0,E19<0),-(G19-E19)/E19,IF(ISERROR(G19/E19),"-",(G19-E19)/E19)))),"-") -> - | K19: ='PL_25 우리'!Q89/1000000-K20 -> 12.243907 | L19: =IFERROR(K19/K$11,"-") -> 0.033221859 | M19: =18-M20 -> 6.3 | N19: =IFERROR(M19/M$11,"-") -> 0.043150685 | O19: ='PL_25 우리'!R89/1000000-O20 -> 92.34805 | P19: =IFERROR(O19/O$11,"-") -> 0.033131272 | R19: =IFERROR(Q19/Q$11,"-") -> - | S19: ='PL_26 우리'!Q91/1000000-S20 -> 50.563642 | T19: =IFERROR(S19/S$11,"-") -> 0.02288704 | U19: =IF(O19<0,(S19-O19)/ABS(O19),(S19-O19)/O19) -> -0.4524666 | V19: =IFERROR(IF(AND(S19<0,Q19<0),-(S19-Q19)/Q19,IF(AND(S19<0,Q19>0),(S19-Q19)/Q19,IF(AND(S19>0,Q19<0),-(S19-Q19)/Q19,IF(ISERROR(S19/Q19),"-",(S19-Q19)/Q19)))),"-") -> - | Y19: =(G19)/(C19)-1 -> -0.60234595 | Z19: =(S19)/(O19)-1 -> -0.4524666 | AC19: 상각비 | AD19: 노무비
B20: 간접 인건비 | C20: 11.7 | D20: =IFERROR(C20/C$11,"-") -> 0.031326911 | F20: =IFERROR(E20/E$11,"-") -> - | G20: =11.7 -> 11.7 | H20: =IFERROR(G20/G$11,"-") -> 0.087509897 | I20: =IFERROR(IF(ROUND(C20,0)<0, (ROUND(G20,0)-ROUND(C20,0))/ABS(ROUND(C20,0)), (ROUND(G20,0)-ROUND(C20,0))/ROUND(C20,0)), "-") -> 0 | J20: =IFERROR(IF(AND(G20<0,E20<0),-(G20-E20)/E20,IF(AND(G20<0,E20>0),(G20-E20)/E20,IF(AND(G20>0,E20<0),-(G20-E20)/E20,IF(ISERROR(G20/E20),"-",(G20-E20)/E20)))),"-") -> - | K20: 12 | L20: =IFERROR(K20/K$11,"-") -> 0.032560057 | M20: =11.7 -> 11.7 | N20: =IFERROR(M20/M$11,"-") -> 0.080136986 | O20: =11.7*7+2 -> 83.9 | P20: =IFERROR(O20/O$11,"-") -> 0.030100405 | R20: =IFERROR(Q20/Q$11,"-") -> - | S20: =(11.7*6)+G20+1 -> 82.9 | T20: =IFERROR(S20/S$11,"-") -> 0.037523714 | U20: =IF(O20<0,(S20-O20)/ABS(O20),(S20-O20)/O20) -> -0.011918951 | V20: =IFERROR(IF(AND(S20<0,Q20<0),-(S20-Q20)/Q20,IF(AND(S20<0,Q20>0),(S20-Q20)/Q20,IF(AND(S20>0,Q20<0),-(S20-Q20)/Q20,IF(ISERROR(S20/Q20),"-",(S20-Q20)/Q20)))),"-") -> - | Y20: =(G20)/(C20)-1 -> 0 | Z20: =(S20)/(O20)-1 -> -0.011918951 | AC20: 인세 | AD20: 무형자산상각비
B21: 관리비 | C21: =('PL_25 우리'!P91-'PL_25 우리'!P65-'PL_25 우리'!P66)/1000000 -> 6.572637 | D21: =IFERROR(C21/C$11,"-") -> 0.017598326 | F21: =IFERROR(E21/E$11,"-") -> - | G21: =('PL_26 우리'!P93-'PL_26 우리'!P67-'PL_26 우리'!P66)/1000000 -> 11.020745 | H21: =IFERROR(G21/G$11,"-") -> 0.082429424 | I21: =IFERROR(IF(ROUND(C21,0)<0, (ROUND(G21,0)-ROUND(C21,0))/ABS(ROUND(C21,0)), (ROUND(G21,0)-ROUND(C21,0))/ROUND(C21,0)), "-") -> 0.57142857 | J21: =IFERROR(IF(AND(G21<0,E21<0),-(G21-E21)/E21,IF(AND(G21<0,E21>0),(G21-E21)/E21,IF(AND(G21>0,E21<0),-(G21-E21)/E21,IF(ISERROR(G21/E21),"-",(G21-E21)/E21)))),"-") -> - | K21: =('PL_25 우리'!Q91-'PL_25 우리'!Q65-'PL_25 우리'!Q66)/1000000 -> 6.196322 | L21: =IFERROR(K21/K$11,"-") -> 0.016812717 | M21: 6 | N21: =IFERROR(M21/M$11,"-") -> 0.04109589 | O21: =('PL_25 우리'!R91)/1000000 -> 123.40447 | P21: =IFERROR(O21/O$11,"-") -> 0.044273238 | R21: =IFERROR(Q21/Q$11,"-") -> - | S21: =('PL_26 우리'!Q93-'PL_26 우리'!Q67-'PL_26 우리'!Q66)/1000000 -> 75.575191 | T21: =IFERROR(S21/S$11,"-") -> 0.034208225 | U21: =IF(O21<0,(S21-O21)/ABS(O21),(S21-O21)/O21) -> -0.38758143 | V21: =IFERROR(IF(AND(S21<0,Q21<0),-(S21-Q21)/Q21,IF(AND(S21<0,Q21>0),(S21-Q21)/Q21,IF(AND(S21>0,Q21<0),-(S21-Q21)/Q21,IF(ISERROR(S21/Q21),"-",(S21-Q21)/Q21)))),"-") -> - | Y21: =(G21)/(C21)-1 -> 0.67676155 | Z21: =(S21)/(O21)-1 -> -0.38758143 | AC21: 경비 | AD21: 기타경비
B22: 감가상각비 | C22: ='PL_25 우리'!P92/1000000 -> 0.30113 | D22: =IFERROR(C22/C$11,"-") -> 0.00080627972 | F22: =IFERROR(E22/E$11,"-") -> - | G22: ='PL_26 우리'!P94/1000000 -> 0.30113 | H22: =IFERROR(G22/G$11,"-") -> 0.0022522953 | I22: =IFERROR(IF(ROUND(C22,0)<0, (ROUND(G22,0)-ROUND(C22,0))/ABS(ROUND(C22,0)), (ROUND(G22,0)-ROUND(C22,0))/ROUND(C22,0)), "-") -> - | J22: =IFERROR(IF(AND(G22<0,E22<0),-(G22-E22)/E22,IF(AND(G22<0,E22>0),(G22-E22)/E22,IF(AND(G22>0,E22<0),-(G22-E22)/E22,IF(ISERROR(G22/E22),"-",(G22-E22)/E22)))),"-") -> - | K22: ='PL_25 우리'!Q92/1000000 -> 0.30113 | L22: =IFERROR(K22/K$11,"-") -> 0.0008170675 | M22: 0 | N22: =IFERROR(M22/M$11,"-") -> 0 | O22: ='PL_25 우리'!R92/1000000 -> 2.10791 | P22: =IFERROR(O22/O$11,"-") -> 0.00075624488 | R22: =IFERROR(Q22/Q$11,"-") -> - | S22: ='PL_26 우리'!Q94/1000000 -> 2.10791 | T22: =IFERROR(S22/S$11,"-") -> 0.00095412076 | U22: =IF(O22<0,(S22-O22)/ABS(O22),(S22-O22)/O22) -> 0 | V22: =IFERROR(IF(AND(S22<0,Q22<0),-(S22-Q22)/Q22,IF(AND(S22<0,Q22>0),(S22-Q22)/Q22,IF(AND(S22>0,Q22<0),-(S22-Q22)/Q22,IF(ISERROR(S22/Q22),"-",(S22-Q22)/Q22)))),"-") -> - | Y22: =(G22)/(C22)-1 -> 0 | Z22: =(S22)/(O22)-1 -> 0
B23: 판매 및 관리비 | C23: =SUM(C19:C22) -> 33.34059 | D23: =IFERROR(C23/C$11,"-") -> 0.089269889 | E23: =SUM(E19:E22) -> 0 | F23: =IFERROR(E23/E$11,"-") -> - | G23: =SUM(G19:G22) -> 28.893962 | H23: =IFERROR(G23/G$11,"-") -> 0.21611176 | I23: =IFERROR(IF(ROUND(C23,0)<0, (ROUND(G23,0)-ROUND(C23,0))/ABS(ROUND(C23,0)), (ROUND(G23,0)-ROUND(C23,0))/ROUND(C23,0)), "-") -> -0.12121212 | J23: =IFERROR(IF(AND(G23<0,E23<0),-(G23-E23)/E23,IF(AND(G23<0,E23>0),(G23-E23)/E23,IF(AND(G23>0,E23<0),-(G23-E23)/E23,IF(ISERROR(G23/E23),"-",(G23-E23)/E23)))),"-") -> - | K23: =SUM(K19:K22) -> 30.741359 | L23: =IFERROR(K23/K$11,"-") -> 0.083411701 | M23: =SUM(M19:M22) -> 24 | N23: =IFERROR(M23/M$11,"-") -> 0.16438356 | O23: =SUM(O19:O22) -> 301.76043 | P23: =IFERROR(O23/O$11,"-") -> 0.10826116 | Q23: =SUM(Q19:Q22) -> 0 | R23: =IFERROR(Q23/Q$11,"-") -> - | S23: =SUM(S19:S22) -> 211.14674 | T23: =IFERROR(S23/S$11,"-") -> 0.095573099 | U23: =IF(O23<0,(S23-O23)/ABS(O23),(S23-O23)/O23) -> -0.30028354 | V23: =IFERROR(IF(AND(S23<0,Q23<0),-(S23-Q23)/Q23,IF(AND(S23<0,Q23>0),(S23-Q23)/Q23,IF(AND(S23>0,Q23<0),-(S23-Q23)/Q23,IF(ISERROR(S23/Q23),"-",(S23-Q23)/Q23)))),"-") -> - | Y23: =(G23)/(C23)-1 -> -0.13336981 | Z23: =(S23)/(O23)-1 -> -0.30028354
B24: 영업이익 | C24: =C18-C23 -> -20.554104 | D24: =IFERROR(C24/C$11,"-") -> -0.055033896 | E24: =E18-E23 -> 0 | F24: =IFERROR(E24/E$11,"-") -> - | G24: =G18-G23 -> 4.735668 | H24: =IFERROR(G24/G$11,"-") -> 0.035420326 | I24: =IFERROR(IF(ROUND(C24,0)<0, (ROUND(G24,0)-ROUND(C24,0))/ABS(ROUND(C24,0)), (ROUND(G24,0)-ROUND(C24,0))/ROUND(C24,0)), "-") -> 1.2380952 | J24: =IFERROR(IF(AND(G24<0,E24<0),-(G24-E24)/E24,IF(AND(G24<0,E24>0),(G24-E24)/E24,IF(AND(G24>0,E24<0),-(G24-E24)/E24,IF(ISERROR(G24/E24),"-",(G24-E24)/E24)))),"-") -> - | K24: =K18-K23 -> -21.022293 | L24: =IFERROR(K24/K$11,"-") -> -0.057040589 | M24: =M18-M23 -> -23 | N24: =IFERROR(M24/M$11,"-") -> -0.15753425 | O24: =O18-O23 -> -240.401 | P24: =IFERROR(O24/O$11,"-") -> -0.086247527 | Q24: =Q18-Q23 -> 0 | R24: =IFERROR(Q24/Q$11,"-") -> - | S24: =S18-S23 -> 70.627136 | T24: =IFERROR(S24/S$11,"-") -> 0.031968546 | U24: =IF(O24<0,(S24-O24)/ABS(O24),(S24-O24)/O24) -> 1.2937889 | V24: =IFERROR(IF(AND(S24<0,Q24<0),-(S24-Q24)/Q24,IF(AND(S24<0,Q24>0),(S24-Q24)/Q24,IF(AND(S24>0,Q24<0),-(S24-Q24)/Q24,IF(ISERROR(S24/Q24),"-",(S24-Q24)/Q24)))),"-") -> - | Y24: =(G24-C24)/-G24 -> -5.3402755 | Z24: =(S24-O24)/-S24 -> -4.403805 | AC24: 우리인터텍스
B25: 영업외수익 | C25: ='PL_25 우리'!P70/1000000 -> 8.708974 | D25: =IFERROR(C25/C$11,"-") -> 0.023318398 | F25: =IFERROR(E25/E$11,"-") -> - | G25: =('PL_26 우리'!P71)/1000000 -> 14.097792 | H25: =IFERROR(G25/G$11,"-") -> 0.10544413 | I25: =IFERROR(IF(ROUND(C25,0)<0, (ROUND(G25,0)-ROUND(C25,0))/ABS(ROUND(C25,0)), (ROUND(G25,0)-ROUND(C25,0))/ROUND(C25,0)), "-") -> 0.55555556 | J25: =IFERROR(IF(AND(G25<0,E25<0),-(G25-E25)/E25,IF(AND(G25<0,E25>0),(G25-E25)/E25,IF(AND(G25>0,E25<0),-(G25-E25)/E25,IF(ISERROR(G25/E25),"-",(G25-E25)/E25)))),"-") -> - | K25: ='PL_25 우리'!Q70/1000000 -> 22.569653 | L25: =IFERROR(K25/K$11,"-") -> 0.061239099 | M25: 10 | N25: =IFERROR(M25/M$11,"-") -> 0.068493151 | O25: ='PL_25 우리'!R70/1000000 -> 165.49964 | P25: =IFERROR(O25/O$11,"-") -> 0.059375521 | R25: =IFERROR(Q25/Q$11,"-") -> - | S25: ='PL_26 우리'!Q71/1000000 -> 124.46114 | T25: =IFERROR(S25/S$11,"-") -> 0.056335876 | U25: =IF(O25<0,(S25-O25)/ABS(O25),(S25-O25)/O25) -> -0.24796731 | V25: =IFERROR(IF(AND(S25<0,Q25<0),-(S25-Q25)/Q25,IF(AND(S25<0,Q25>0),(S25-Q25)/Q25,IF(AND(S25>0,Q25<0),-(S25-Q25)/Q25,IF(ISERROR(S25/Q25),"-",(S25-Q25)/Q25)))),"-") -> - | Y25: =(G25)/(C25)-1 -> 0.61876611 | Z25: =(S25)/(O25)-1 -> -0.24796731 | AC25: 2016년 | AD25: 2017년 | AE25: 달라지는 점
B26: 영업외비용 | C26: ='PL_25 우리'!P76/1000000 -> 191.30615 | D26: =IFERROR(C26/C$11,"-") -> 0.51222486 | F26: =IFERROR(E26/E$11,"-") -> - | G26: =('PL_26 우리'!P77)/1000000 -> 100.64484 | H26: =IFERROR(G26/G$11,"-") -> 0.75277091 | I26: =IFERROR(IF(ROUND(C26,0)<0, (ROUND(G26,0)-ROUND(C26,0))/ABS(ROUND(C26,0)), (ROUND(G26,0)-ROUND(C26,0))/ROUND(C26,0)), "-") -> -0.47120419 | J26: =IFERROR(IF(AND(G26<0,E26<0),-(G26-E26)/E26,IF(AND(G26<0,E26>0),(G26-E26)/E26,IF(AND(G26>0,E26<0),-(G26-E26)/E26,IF(ISERROR(G26/E26),"-",(G26-E26)/E26)))),"-") -> - | K26: ='PL_25 우리'!Q76/1000000 -> 197.92329 | L26: =IFERROR(K26/K$11,"-") -> 0.5370328 | M26: 97 | N26: =IFERROR(M26/M$11,"-") -> 0.66438356 | O26: ='PL_25 우리'!R76/1000000 -> 1327.8136 | P26: =IFERROR(O26/O$11,"-") -> 0.47637339 | R26: =IFERROR(Q26/Q$11,"-") -> - | S26: ='PL_26 우리'!Q77/1000000 -> 754.43716 | T26: =IFERROR(S26/S$11,"-") -> 0.34148714 | U26: =IF(O26<0,(S26-O26)/ABS(O26),(S26-O26)/O26) -> -0.43181998 | V26: =IFERROR(IF(AND(S26<0,Q26<0),-(S26-Q26)/Q26,IF(AND(S26<0,Q26>0),(S26-Q26)/Q26,IF(AND(S26>0,Q26<0),-(S26-Q26)/Q26,IF(ISERROR(S26/Q26),"-",(S26-Q26)/Q26)))),"-") -> - | Y26: =(G26)/(C26)-1 -> -0.47390693 | Z26: =(S26)/(O26)-1 -> -0.43181998 | AC26: 재료비 | AD26: 재료비 | AE26: 재료비와 부재료비를 재료비 항목으로 통합
B27: 경상이익 | C27: =C24+C25-C26 -> -203.15128 | D27: =IFERROR(C27/C$11,"-") -> -0.54394036 | E27: =E24+E25-E26 -> 0 | F27: =IFERROR(E27/E$11,"-") -> - | G27: =G24+G25-G26 -> -81.811381 | H27: =IFERROR(G27/G$11,"-") -> -0.61190646 | I27: =IFERROR(IF(ROUND(C27,0)<0, (ROUND(G27,0)-ROUND(C27,0))/ABS(ROUND(C27,0)), (ROUND(G27,0)-ROUND(C27,0))/ROUND(C27,0)), "-") -> 0.59605911 | J27: =IFERROR(IF(AND(G27<0,E27<0),-(G27-E27)/E27,IF(AND(G27<0,E27>0),(G27-E27)/E27,IF(AND(G27>0,E27<0),-(G27-E27)/E27,IF(ISERROR(G27/E27),"-",(G27-E27)/E27)))),"-") -> - | K27: =K24+K25-K26 -> -196.37593 | L27: =IFERROR(K27/K$11,"-") -> -0.53283428 | M27: =M24+M25-M26 -> -110 | N27: =IFERROR(M27/M$11,"-") -> -0.75342466 | O27: =O24+O25-O26+0.2 -> -1402.515 | P27: =IFERROR(O27/O$11,"-") -> -0.50317364 | Q27: =Q24+Q25-Q26 -> 0 | R27: =IFERROR(Q27/Q$11,"-") -> - | S27: =S24+S25-S26 -> -559.34888 | T27: =IFERROR(S27/S$11,"-") -> -0.25318272 | U27: =IF(O27<0,(S27-O27)/ABS(O27),(S27-O27)/O27) -> 0.60118152 | V27: =IFERROR(IF(AND(S27<0,Q27<0),-(S27-Q27)/Q27,IF(AND(S27<0,Q27>0),(S27-Q27)/Q27,IF(AND(S27>0,Q27<0),-(S27-Q27)/Q27,IF(ISERROR(S27/Q27),"-",(S27-Q27)/Q27)))),"-") -> - | Y27: =(G27-C27)/-G27 -> 1.4831665 | Z27: =(S27-O27)/-S27 -> 1.5074064 | AC27: 부재료비
AC28: 노무비 | AD28: 외주가공비 | AE28: 금액이 크지 않다면 노무비를 기타경비에 포함하고,
B29: 당월 주요사항 | L29: 차월 주요사항 | AC29: 경비 | AD29: 기타경비 | AE29: 경비를 외주가공비와 기타경비로 구분
B30: 1. 매출액 | L30: 1. 매출액
B31: 1) 상품매출 134백만원 | L31: 1) 상품매출 146백만원
B33: 2. 영업외비용 | L33: 2. 영업외비용
B34: 1) 푸른저축은행 마이너스통장 15억(8.3%) | L34: 1) 푸른저축은행 마이너스통장(대출), 이자율 8.3%('26.04.11~'27.04.10)
L35: - '26.04.11 대출연장 미사용 한도감소 24억→15억

Sheet 재무 및 현금흐름 현황
B1: 2. 재무 현황
V3: (단위:백만원)
B4: 구분 | D4: 2025년 | H4: 2026년 | P4: 주요 증감내역
D5: 전년말 실적 | H5: 7월 실적 -당월 | L5: 전기말 대비 증감
B6: 유동자산 | D6: =BS_우리인터텍스!E4/1000000 -> 1792.8609 | F6: =IFERROR(D6/D$8,"-") -> 0.072536958 | H6: =BS_우리인터텍스!C4/1000000 -> 2657.4463 | J6: =IFERROR(H6/H$8,"-") -> 0.10848128 | L6: =H6-D6 -> 864.58536 | N6: =(H6)/(D6)-1 -> 0.48223783
B7: 비유동자산 | D7: =BS_우리인터텍스!E24/1000000 -> 22923.656 | F7: =IFERROR(D7/D$8,"-") -> 0.92746304 | H7: =BS_우리인터텍스!C24/1000000 -> 21839.374 | J7: =IFERROR(H7/H$8,"-") -> 0.89151872 | L7: =H7-D7 -> -1084.2819 | N7: =(H7)/(D7)-1 -> -0.047299694 | P7: 사무실 임차보증금 15억 회수 및 감가상각누계액
B8: 자산총계 | D8: =SUM(D6:E7) -> 24716.517 | F8: =IFERROR(D8/D$8,"-") -> 1 | H8: =SUM(H6:I7) -> 24496.82 | J8: =IFERROR(H8/H$8,"-") -> 1 | L8: =SUM(L6:M7) -> -219.69654 | N8: =(H8)/(D8)-1 -> -0.008888653
B9: 유동부채 | D9: =BS_우리인터텍스!E48/1000000 -> 24091.033 | F9: =IFERROR(D9/D$8,"-") -> 0.97469371 | H9: =BS_우리인터텍스!C48/1000000 -> 24430.686 | J9: =IFERROR(H9/H$8,"-") -> 0.99730028 | L9: =H9-D9 -> 339.65234 | N9: =(H9)/(D9)-1 -> 0.014098704
B10: 비유동부채 | D10: =BS_우리인터텍스!E59/1000000 -> 0 | F10: =IFERROR(D10/D$8,"-") -> 0 | H10: =(BS_우리인터텍스!C59)/1000000 -> 0 | J10: =IFERROR(H10/H$8,"-") -> 0 | L10: =H10-D10 -> 0 | N10: =IFERROR(L10/D10,"-") -> -
B11: (차입금) | D11: =(BS_우리인터텍스!E55+BS_우리인터텍스!E58+BS_우리인터텍스!E60)/1000000 -> 19894.576 | F11: =IFERROR(D11/D$8,"-") -> 0.8049102 | H11: =(BS_우리인터텍스!C55+BS_우리인터텍스!C60+BS_우리인터텍스!C58)/1000000 -> 20363.181 | J11: =IFERROR(H11/H$8,"-") -> 0.83125813 | L11: =H11-D11 -> 468.60444 | N11: =(H11)/(D11)-1 -> 0.023554382
B12: 부채총계 | D12: =SUM(D9:E10) -> 24091.033 | F12: =IFERROR(D12/D$8,"-") -> 0.97469371 | H12: =SUM(H9:I10) -> 24430.686 | J12: =IFERROR(H12/H$8,"-") -> 0.99730028 | L12: =SUM(L9:M10) -> 339.65234 | N12: =(H12)/(D12)-1 -> 0.014098704
B13: 자본금 | D13: =(BS_우리인터텍스!E63/1000000) -> 17858.5 | F13: =IFERROR(D13/D$8,"-") -> 0.72253304 | H13: =(BS_우리인터텍스!C63)/1000000 -> 17858.5 | J13: =IFERROR(H13/H$8,"-") -> 0.72901299 | L13: =H13-D13 -> 0 | N13: =(H13)/(D13)-1 -> 0
B14: 기타자본항목 | D14: =(BS_우리인터텍스!E66/1000000) -> 3974.5056 | F14: =IFERROR(D14/D$8,"-") -> 0.16080363 | H14: =(BS_우리인터텍스!C66)/1000000 -> 3974.5056 | J14: =IFERROR(H14/H$8,"-") -> 0.16224578 | L14: =H14-D14 -> 0 | N14: =(H14)/(D14)-1 -> 0
B15: 자본조정 | D15: =(BS_우리인터텍스!E67/1000000) -> -94.14824 | F15: =IFERROR(D15/D$8,"-") -> -0.0038091225 | H15: =(BS_우리인터텍스!C67)/1000000 -> -94.14824 | J15: =IFERROR(H15/H$8,"-") -> -0.0038432841 | L15: =H15-D15 -> 0 | N15: =(H15)/(D15)-1 -> 0 | P15: 주식할인발행차금
B16: 기타포괄손익누계액 | D16: =(BS_우리인터텍스!E69/1000000) -> 89.642512 | F16: =IFERROR(D16/D$8,"-") -> 0.0036268263 | H16: =(BS_우리인터텍스!C69)/1000000 -> 89.642512 | J16: =IFERROR(H16/H$8,"-") -> 0.003659353 | L16: =H16-D16 -> 0 | N16: =(H16)/(D16)-1 -> 0
B17: 이익잉여금(미처리결손금) | D17: =-BS_우리인터텍스!E71/1000000 -> -21203.016 | F17: =IFERROR(D17/D$8,"-") -> -0.85784809 | H17: =-BS_우리인터텍스!C71/1000000 -> -21762.365 | J17: =IFERROR(H17/H$8,"-") -> -0.88837512 | L17: =H17-D17 -> -559.34888 | N17: =IF(D17<0,(H17-D17)/ABS(D17),(H17-D17)/D17) -> -0.026380628 | P17: 결손금 증가
B18: 자본총계 | D18: =SUM(D13:D17) -> 625.48338 | F18: =IFERROR(D18/D$8,"-") -> 0.025306292 | H18: =SUM(H13:H17) -> 66.134495 | J18: =IFERROR(H18/H$8,"-") -> 0.0026997175 | L18: =SUM(L13:L17) -> -559.34888 | N18: =(H18-D18)/D18 -> -0.89426658 | P18: 자본 감소
B20: 부채비율 | D20: =(D12-D18)/-D12 -> -0.97403667 | H20: =(H12-H18)/-H12 -> -0.99729297 | L20: =H20-D20 -> -0.023256301
B21: 유동비율 | D21: =D6/D9 -> 0.074420258 | H21: =H6/H9 -> 0.10877494 | L21: =H21-D21 -> 0.034354678 | P21: 유동자산 / 유동부채
B22: 차입금의존도 | D22: =D11/D8 -> 0.8049102 | H22: =H11/H8 -> 0.83125813 | L22: =H22-D22 -> 0.026347927 | P22: 차입금 / 자산총계
B23: 자본잠식률 | D23: =-IFERROR(D18/D8,"-") -> -0.025306292 | H23: =-IFERROR(H18/H8,"-") -> -0.0026997175 | L23: =H23-D23 -> 0.022606574 | P23: △자본총계 / 자산총계
B25: 3. 현금흐름 현황
A26: 44846
V27: (단위:백만원)
B28: 구 분 | E28: 전월 현금흐름 현황 | G28: 당월 현금흐름 현황 | I28: 차월 현금흐름계획 | K28: 주요 내역
E29: 2026년 7월 | G29: 2026년 8월 | I29: 2026년 9월 | K29: 2026년 7월 | O29: 2026년 8월 | S29: 2026년 9월
B30: 기초잔액 | E30: 5 | G30: =E47 -> 566 | I30: =G47 -> 523.9
B31: 매출채권 회수(매출) | E31: 365 | G31: 396.7 | I31: 255
B32: 기타 운전자본증감
B33: 기타 영업활동 수입(영업외수익) | E33: 4 | G33: 1.8
B34: 영업활동 수입 | E34: =SUM(E31:F33) -> 369 | G34: =SUM(G31:H33) -> 398.5 | I34: =SUM(I31:J33) -> 255
B35: 매입채무 지급(매출원가) | G35: 403 | I35: 362
B36: 기타 영업활동 지출(판관비) | E36: 48 | G36: 24 | I36: 23 | K36: 원천세 및 부가세 납부
B37: 기타 영업활동 지출(영업외비용) | E37: 37 | G37: 13.6 | I37: 51 | K37: 이자지출 | O37: 이자지출 | S37: 이자지출
B38: 영업활동 지출 | E38: =SUM(E35:F37) -> 85 | G38: =SUM(G35:H37) -> 440.6 | I38: =SUM(I35:J37) -> 436
B39: 영업활동 현금흐름 | E39: =E34-E38 -> 284 | G39: =G34-G38 -> -42.1 | I39: =I34-I38 -> -181
B40: 투자활동 수입 | E40: 1200 | K40: 보증금 회수
B41: 투자활동 지출
B42: 투자활동 현금흐름 | E42: =E40-E41 -> 1200 | G42: =G40-G41 -> 0 | I42: =I40-I41 -> 0
B43: 재무활동 수입 | E43: 1457 | K43: 차입금
...

Sheet 인원 및 투자 현황
B1: 4. 인원 현황
V3: (단위:명)
B4: 부서 | D4: 2025년 현황 | G4: 2026년 현황 | Q4: 비고
D5: 전년말 현황 | G5: 사업계획 | J5: 7월 현황 - 당월 | M5: 전년말대비 | O5: 계획대비
B6: 대표 | D6: 1 | F6: =IFERROR(D6/D$15,"-") -> 0.25 | G6: 1 | I6: =IFERROR(G6/G$15,"-") -> 0.25 | J6: 1 | L6: =IFERROR(J6/J$15,"-") -> 0.33333333 | M6: =J6-D6 -> 0 | O6: =J6-G6 -> 0
B7: 임원 | D7: 1 | F7: =IFERROR(D7/D$15,"-") -> 0.25 | G7: 1 | I7: =IFERROR(G7/G$15,"-") -> 0.25 | J7: 1 | L7: =IFERROR(J7/J$15,"-") -> 0.33333333 | M7: =J7-D7 -> 0 | O7: =J7-G7 -> 0
B8: 기획관리팀 | D8: 1 | F8: =IFERROR(D8/D$15,"-") -> 0.25 | G8: 1 | I8: =IFERROR(G8/G$15,"-") -> 0.25 | J8: 1 | L8: =IFERROR(J8/J$15,"-") -> 0.33333333 | M8: =J8-D8 -> 0 | O8: =J8-G8 -> 0
B9: 영업/기획팀 | D9: 1 | F9: =IFERROR(D9/D$15,"-") -> 0.25 | G9: 1 | I9: =IFERROR(G9/G$15,"-") -> 0.25 | J9: 0 | L9: =IFERROR(J9/J$15,"-") -> 0 | M9: =J9-D9 -> -1 | O9: =J9-G9 -> -1
B10: 계약직 | D10: 0 | F10: =IFERROR(D10/D$15,"-") -> 0 | G10: 0 | I10: =IFERROR(G10/G$15,"-") -> 0 | J10: 0 | L10: =IFERROR(J10/J$15,"-") -> 0 | M10: =J10-D10 -> 0 | O10: =J10-G10 -> 0
B11: 파견직 | D11: 0 | F11: =IFERROR(D11/D$15,"-") -> 0 | G11: 0 | I11: =IFERROR(G11/G$15,"-") -> 0 | J11: 0 | L11: =IFERROR(J11/J$15,"-") -> 0 | M11: =J11-D11 -> 0 | O11: =J11-G11 -> 0
B15: 합계 | D15: =SUM(D6:E14) -> 4 | F15: =IFERROR(D15/D$15,"-") -> 1 | G15: =SUM(G6:H14) -> 4 | I15: =IFERROR(G15/G$15,"-") -> 1 | J15: =SUM(J6:K14) -> 3 | L15: =IFERROR(J15/J$15,"-") -> 1 | M15: =SUM(M6:N14) -> -1 | O15: =SUM(O6:P14) -> -1
B17: 5. 투자 현황
V19: (단위:백만원)
B20: 구 분 | C20: 2025년 현황 | F20: 2026년 | I20: =J5 -> 7월 현황 - 당월 | M20: 2026년 연간 누계실적 | Q20: 8월 예상 - 차월 | U20: 비고
C21: 전년말 현황 | F21: 사업계획 | I21: 계획 | K21: 실적 | M21: 계획 | O21: 실적 | Q21: 계획 | S21: 예상
B22: 투자자산 | C22: 0 | E22: =IFERROR(C22/$C$28,"-") -> - | F22: 0 | H22: =IFERROR(F22/$F$28,"-") -> - | K22: 0 | M22: 0 | O22: =(BS_우리인터텍스!C25/1000000)-BS_우리인터텍스!E25/1000000 -> 0 | Q22: 0 | S22: 0
A23: 44846 | B23: 유형자산 | C23: 0 | E23: =IFERROR(C23/$C$28,"-") -> - | F23: 0 | H23: =IFERROR(F23/$F$28,"-") -> - | I23: 0 | K23: 0 | M23: 0 | O23: =(BS_우리인터텍스!C29/1000000)-BS_우리인터텍스!E29/1000000 -> -2.10791 | Q23: 0 | S23: 0
B24: 무형자산 | C24: 0 | E24: =IFERROR(C24/$C$28,"-") -> - | F24: 0 | H24: =IFERROR(F24/$F$28,"-") -> - | I24: 0 | K24: 0 | M24: 0 | O24: =(BS_우리인터텍스!C38/1000000)-BS_우리인터텍스!E38/1000000 -> 0 | Q24: 0 | S24: 0
B25: 임차보증금 | C25: 0 | E25: =IFERROR(C25/$C$28,"-") -> - | F25: 0 | H25: =IFERROR(F25/$F$28,"-") -> - | I25: 0 | K25: 0 | M25: 0 | O25: =(BS_우리인터텍스!C42/1000000)-BS_우리인터텍스!E42/1000000 -> -1500 | Q25: 0 | S25: 0
B26: 기타보증금 | C26: 0 | E26: =IFERROR(C26/$C$28,"-") -> - | F26: 0 | H26: =IFERROR(F26/$F$28,"-") -> - | I26: 0 | K26: 0 | M26: 0 | O26: =(BS_우리인터텍스!C43/1000000)-BS_우리인터텍스!E43/1000000 -> 417.82601 | Q26: 0 | S26: 0
B28: 합계 | C28: =SUM(C22:D27) -> 0 | E28: =SUM(E22:E27) -> 0 | F28: =SUM(F22:G27) -> 0 | H28: =SUM(H22:H27) -> 0 | I28: =SUM(I22:J27) -> 0 | K28: =SUM(K22:L27) -> 0 | M28: =SUM(M22:N27) -> 0 | O28: =SUM(O22:P27) -> -1084.2819 | Q28: =SUM(Q22:R27) -> 0 | S28: =SUM(S22:T27) -> 0
B30: 주요투자내역 (당월) | O30: (차월)

Sheet PL_25 우리
A1: 과목 | B1: 합계 | C1: 2025년 1월 | D1: 2025년 2월 | E1: 2025년 3월 | F1: 2025년 4월 | G1: 2025년 5월 | H1: 2025년 6월 | I1: 2025년 7월 | J1: 2025년 8월 | K1: 2025년 9월 | L1: 2025년 10월 | M1: 2025년 11월 | N1: 2025년 12월 | P1: 당월 | Q1: 차월 | R1: 연간누계
A2: Ⅰ.원재료비 | B2: =B3+B4-B5 -> 0 | C2: =C3+C4-C5 -> 0 | D2: =D3+D4-D5 -> 0 | E2: =E3+E4-E5 -> 0 | F2: =F3+F4-F5 -> 0 | G2: =G3+G4-G5 -> 0 | H2: =H3+H4-H5 -> 0 | I2: =I3+I4-I5 -> 0 | ... N2: =N3+N4-N5 -> 0 | P2: =N2 -> 0 | Q2: =N2 -> 0 | R2: =SUM(C2:M2) -> 0 | S2: =R2=B2 -> 1 | T2: =R3+R4-R5 -> 0
A3: 기 초 원재료재고액 | B3: =SUM(C3) -> 0 | P3: =N3 -> 0 | Q3: =N3 -> 0 | R3: =C3 -> 0 | S3: =R3=B3 -> 1
A4: 당 기 원재료매입액 | B4: =SUM(C4:N4) -> 0 | P4: =N4 -> 0 | Q4: =N4 -> 0 | R4: =SUM(C4:M4) -> 0 | S4: =R4=B4 -> 1
A5: 기 말 원재료재고액 | B5: =N5 -> 0 | P5: =N5 -> 0 | Q5: =N5 -> 0 | R5: =M5 -> 0 | S5: =R5=B5 -> 1
A6: Ⅱ.부재료비 | B6: =B7+B8-B9 -> 0 | C6: =C7+C8-C9 -> 0 | D6: =D7+D8-D9 -> 0 | E6: =E7+E8-E9 -> 0 | F6: =F7+F8-F9 -> 0 | G6: =G7+G8-G9 -> 0 | H6: =H7+H8-H9 -> 0 | I6: =I7+I8-I9 -> 0 | ... N6: =N7+N8-N9 -> 0 | P6: =N6 -> 0 | Q6: =N6 -> 0 | R6: =SUM(C6:N6) -> 0 | S6: =R6=B6 -> 1
A7: 기 초 부재료재고액 | B7: =C7:C7 -> 0 | C7: 0 | D7: =C9 -> 0 | E7: =D9 -> 0 | F7: =E9 -> 0 | G7: =F9 -> 0 | H7: =G9 -> 0 | I7: =H9 -> 0 | J7: =I9 -> 0 | K7: =J9 -> 0 | ... N7: =M9 -> 0 | P7: =N7 -> 0 | Q7: =N7 -> 0 | R7: =SUM(C7) -> 0 | S7: =R7=B7 -> 1
A8: 당 기 부재료매입액 | B8: =SUM(C8:N8) -> 0 | P8: =N8 -> 0 | Q8: =N8 -> 0 | R8: =SUM(C8:E8) -> 0 | S8: =R8=B8 -> 1
A9: 기 말 부재료재고액 | B9: =N9 -> 0 | F9: 0 | P9: =N9 -> 0 | Q9: =N9 -> 0 | R9: =SUM(C9:N9) -> 0 | S9: =R9=B9 -> 1
A10: Ⅲ.노무비 | B10: =B11 -> 0 | C10: =C11 -> 0 | D10: =D11 -> 0 | E10: =E11 -> 0 | F10: =F11 -> 0 | G10: =G11 -> 0 | H10: =H11 -> 0 | I10: =I11 -> 0 | ... N10: =N11 -> 0 | P10: =N10 -> 0 | Q10: =N10 -> 0 | R10: =SUM(C10:N10) -> 0 | S10: =R10=B10 -> 1
A11: 잡 급 | B11: =SUM(C11:N11) -> 0 | P11: =N11 -> 0 | Q11: =N11 -> 0 | R11: =SUM(C11:N11) -> 0 | S11: =R11=B11 -> 1
A12: Ⅳ.경비 | B12: =SUM(B13:B19) -> 0 | C12: =SUM(C13:C19) -> 0 | D12: =SUM(D13:D19) -> 0 | E12: =SUM(E13:E19) -> 0 | F12: =SUM(F13:F19) -> 0 | G12: =SUM(G13:G19) -> 0 | H12: =SUM(H13:H19) -> 0 | I12: =SUM(I13:I19) -> 0 | ... N12: =SUM(N13:N19) -> 0 | P12: =N12 -> 0 | Q12: =N12 -> 0 | R12: =SUM(C12:I12) -> 0 | S12: =R12=B12 -> 1
A13: 복 리 후 생 비 | B13: =SUM(C13:N13) -> 0 | P13: =N13 -> 0 | Q13: =N13 -> 0 | R13: =SUM(C13:I13) -> 0 | S13: =R13=B13 -> 1
A14: 여 비 교 통 비 | B14: =SUM(C14:N14) -> 0 | P14: =N14 -> 0 | Q14: =N14 -> 0 | R14: =SUM(C14:I14) -> 0 | S14: =R14=B14 -> 1
A15: 운 반 비 | B15: =SUM(C15:N15) -> 0 | P15: =N15 -> 0 | Q15: =N15 -> 0 | R15: =SUM(C15:I15) -> 0 | S15: =R15=B15 -> 1
A16: 지 급 수 수 료 | B16: =SUM(C16:N16) -> 0 | P16: =N16 -> 0 | Q16: =N16 -> 0 | R16: =SUM(C16:I16) -> 0 | S16: =R16=B16 -> 1
A17: 외 주 가 공 비 | B17: =SUM(C17:N17) -> 0 | P17: =N17 -> 0 | Q17: =N17 -> 0 | R17: =SUM(C17:I17) -> 0 | S17: =R17=B17 -> 1
A18: 외 주 비 | B18: =SUM(C18:N18) -> 0 | P18: =N18 -> 0 | Q18: =N18 -> 0 | R18: =SUM(C18:I18) -> 0 | S18: =R18=B18 -> 1
A19: 개 발 및 그레이딩 | B19: =SUM(C19:N19) -> 0 | P19: =N19 -> 0 | Q19: =N19 -> 0 | R19: =SUM(C19:I19) -> 0 | S19: =R19=B19 -> 1
A20: Ⅴ.당기총제조비용 | B20: =SUM(C20:N20) -> 0 | C20: =C2+C6+C10+C12 -> 0 | D20: =D2+D6+D10+D12 -> 0 | E20: =E2+E6+E10+E12 -> 0 | F20: =F2+F6+F10+F12 -> 0 | G20: =G2+G6+G10+G12 -> 0 | H20: =H2+H6+H10+H12 -> 0 | I20: =I2+I6+I10+I12 -> 0 | J20: =J2+J6+J10+J12 -> 0 | ... N20: =N2+N6+N10+N12 -> 0 | P20: =N20 -> 0 | Q20: =N20 -> 0 | R20: =SUM(C20:M20) -> 0 | S20: =R20=B20 -> 1
A21: Ⅵ.기초재공품재고액 | P21: =N21 -> 0 | Q21: =N21 -> 0 | R21: =SUM(C21:M21) -> 0 | S21: =R21=B21 -> 1
A22: Ⅶ.타계정에서 대체액 | P22: =N22 -> 0 | Q22: =N22 -> 0 | R22: =SUM(C22:M22) -> 0 | S22: =R22=B22 -> 1
A23: Ⅷ.합계 | B23: =SUM(C23:N23) -> 0 | C23: =C20 -> 0 | D23: =D20 -> 0 | E23: =E20 -> 0 | F23: =F20 -> 0 | G23: =G20 -> 0 | H23: =H20 -> 0 | I23: =I20 -> 0 | J23: =J20 -> 0 | ... N23: =N20 -> 0 | P23: =N23 -> 0 | Q23: =N23 -> 0 | R23: =SUM(C23:M23) -> 0 | S23: =R23=B23 -> 1
A24: Ⅸ.기말재공품재고액 | P24: =N24 -> 0 | Q24: =N24 -> 0 | R24: =SUM(C24:M24) -> 0 | S24: =R24=B24 -> 1
A25: Ⅹ.타계정으로 대체액 | P25: =N25 -> 0 | Q25: =N25 -> 0 | R25: =SUM(C25:M25) -> 0 | S25: =R25=B25 -> 1
A26: ⅩⅠ.당기제품제조원가 | B26: =SUM(C26:N26) -> 0 | C26: =C23 -> 0 | D26: =D23 -> 0 | E26: =E23 -> 0 | F26: =F23 -> 0 | G26: =G23 -> 0 | H26: =H23 -> 0 | I26: =I23 -> 0 | J26: =J23 -> 0 | ... N26: =N23 -> 0 | P26: =N26 -> 0 | Q26: =N26 -> 0 | R26: =SUM(C26:M26) -> 0 | S26: =R26=B26 -> 1
A31: 과목 | B31: 합계 | C31: 2025년 1월 | D31: 2025년 2월 | E31: 2025년 3월 | F31: 2025년 4월 | G31: 2025년 5월 | H31: 2025년 6월 | I31: 2025년 7월 | J31: 2025년 8월 | K31: 2025년 9월 | L31: 2025년 10월 | M31: 2025년 11월 | N31: 2025년 12월 | P31: 당월 | Q31: 차월 | R31: 연간누계
A32: Ⅰ. 매 출 액 | B32: =SUM(C32:N32) -> 5604168480 | C32: =SUM(C33:C36) -> 271823173 | D32: =SUM(D33:D36) -> 176676557 | E32: =SUM(E33:E36) -> 369607483 | F32: =SUM(F33:F36) -> 765435436 | G32: =SUM(G33:G36) -> 580761228 | H32: =SUM(H33:H36) -> 249553187 | I32: =SUM(I33:I36) -> 373480806 | J32: =SUM(J33:J36) -> 368549721 | ... N32: =SUM(N33:N36) -> 199566031 | P32: =I32 -> 373480806 | Q32: =J32 -> 368549721 | R32: =SUM(C32:I32) -> 2787337870 | S32: =R32=B32 -> 0
A33: 상 품 매 출 | B33: =SUM(C33:N33) -> 4115236653 | C33: 131397458 | D33: 107548427 | E33: 258439384 | F33: 562537761 | G33: 350607241 | H33: 183167187 | I33: 199412032 | J33: 81524251 | K33: 241089133 | L33: 855549091 | M33: 944398657 | N33: 199566031 | P33: =I33 -> 199412032 | Q33: =J33 -> 81524251 | R33: =SUM(C33:I33) -> 1793109490 | S33: =R33=B33 -> 0
A34: 제 품 매 출 | B34: =SUM(C34:N34) -> 1488931827 | C34: 140425715 | D34: 69128130 | E34: 111168099 | F34: 202897675 | G34: 230153987 | H34: 66386000 | I34: 174068774 | J34: 287025470 | K34: -113268 | L34: 145198600 | M34: 62592645 | P34: =I34 -> 174068774 | Q34: =J34 -> 287025470 | R34: =SUM(C34:I34) -> 994228380 | S34: =R34=B34 -> 0
A35: 수 출 매 출 | B35: =SUM(C35:N35) -> 0 | P35: =I35 -> 0 | Q35: =J35 -> 0 | R35: =SUM(C35:I35) -> 0
A36: 기 타 매 출 | B36: =SUM(C36:N36) -> 0 | P36: =I36 -> 0 | Q36: =J36 -> 0 | R36: =SUM(C36:I36) -> 0 | S36: =R36=B36 -> 1
A37: Ⅱ. 매 출 원 가 | B37: =SUM(C37:N37) -> 6136760929 | C37: =C38+C42 -> 267318464 | D37: =D38+D42 -> 184678067 | E37: =E38+E42 -> 367096678 | F37: =F38+F42 -> 748535392 | G37: =G38+G42 -> 592105514 | H37: =H38+H42 -> 205624625 | I37: =I38+I42 -> 360619694 | J37: =J38+J42 -> 358818743 | ... N37: =N38+N42 -> 867905800 | P37: =I37 -> 360619694 | Q37: =J37 -> 358818743 | R37: =SUM(C37:I37) -> 2725978434 | S37: =R37=B37 -> 0
A38: 상 품 매 출 원 가 | B38: =B39+B40-B41 -> 4466891913 | C38: =C39+C40-C41 -> 131272864 | D38: =D39+D40-D41 -> 116119227 | E38: =E39+E40-E41 -> 258187003 | F38: =F39+F40-F41 -> 569104326 | G38: =G39+G40-G41 -> 373989737 | H38: =H39+H40-H41 -> 180385169 | I38: =I39+I40-I41 -> 191129425 | ... N38: =N39+N40-N41 -> 579246583 | P38: =I38 -> 191129425 | Q38: =J38 -> 79494185 | R38: =SUM(C38:I38) -> 1820187751 | S38: =R38=B38 -> 0
A39: 기 초 상 품 재고액 | B39: =C39 -> 3171210759 | C39: 3171210759 | D39: 3039937895 | E39: 3066219186 | F39: 2933927779 | G39: 2585142331 | H39: 2250381524 | I39: 2278643287 | J39: 2089352116 | K39: 2103492336 | L39: 2019686921 | M39: 1775735426 | N39: 1668874198 | P39: =I39 -> 2278643287 | Q39: =J39 -> 2089352116 | R39: =SUM(C39) -> 3171210759 | S39: =R39=B39 -> 1
A40: 당 기 상 품 매입액 | B40: =SUM(C40:N40) -> 2385308769 | D40: 142400518 | E40: 125895596 | F40: 220318878 | G40: 39228930 | H40: 208646932 | I40: 1838254 | J40: 93634405 | K40: 170207176 | L40: 595880015 | M40: 787258065 | P40: =I40 -> 1838254 | Q40: =J40 -> 93634405 | R40: =SUM(C40:I40) -> 738329108 | S40: =R40=B40 -> 0
A41: 기 말 상 품 재고액 | B41: =N41 -> 1089627615 | C41: 3039937895 | D41: 3066219186 | E41: 2933927779 | F41: 2585142331 | G41: 2250381524 | H41: 2278643287 | I41: 2089352116 | J41: 2103492336 | K41: 2019686921 | L41: 1775735426 | M41: 1668874198 | N41: 1089627615 | P41: =I41 -> 2089352116 | Q41: =J41 -> 2103492336 | R41: =SUM(I41) -> 2089352116 | S41: =R41=B41 -> 0
A42: 제 품 매 출 원 가 | B42: =B43+B44-B45 -> 1669869016 | C42: =C43+C44-C45 -> 136045600 | D42: =D43+D44-D45 -> 68558840 | E42: =E43+E44-E45 -> 108909675 | F42: =F43+F44-F45 -> 179431066 | G42: =G43+G44-G45 -> 218115777 | H42: =H43+H44-H45 -> 25239456 | I42: =I43+I44-I45 -> 169490269 | ... N42: =N43+N44-N45 -> 288659217 | P42: =I42 -> 169490269 | Q42: =J42 -> 279324558 | R42: =SUM(C42:I42) -> 905790683 | S42: =R42=B42 -> 0 | T42: =R42-B42 -> -764078333
A43: 기 초 제 품 재고액 | B43: =C43 -> 751469884 | C43: 751469884 | D43: 683058611 | E43: 721161038 | F43: 668933119 | G43: 737609226 | H43: 582562241 | I43: 926507774 | J43: 884682925 | K43: 574072606 | L43: 699294546 | M43: 580981450 | N43: 519493449 | P43: =I43 -> 926507774 | Q43: =J43 -> 884682925 | R43: =C43 -> 751469884 | S43: =R43=B43 -> 1
A44: 당 기 제품제조원가 | B44: =SUM(C44:N44) -> 1149233364 | C44: 67634327 | D44: 106661267 | E44: 56681756 | F44: 248107173 | G44: 63068792 | H44: 369184989 | I44: 127665420 | J44: -31285761 | K44: 125110459 | L44: 16524519 | M44: -119577 | P44: =I44 -> 127665420 | Q44: =J44 -> -31285761 | R44: =SUM(C44:I44) -> 1039003724 | S44: =R44=B44 -> 0
...

Sheet 3.주요업무 현황
B1: 주요업무 현황
B4: ▣ 주요업무 추진 현황
B5: 구분 | C5: 6월 주요업무 추진실적 | M5: 7월 주요업무 추진계획
C6: 내용 | M6: 내용
B7: 우리인터텍스 | C7: ▣ 제품 판매 운영 | M7: ▣ 제품 판매 운영
C8: -. 면 티셔츠 개발 검토 | M8: -. 면 티셔츠 샘플 진행예정
C10: ▣ 한국/인도 브랜드 교류 | M10: ▣ 한국/인도 브랜드 교류
C11: -. 생산 관리 및 수입통관, 납품 진행중 | M11: -. 생산 관리 및 수입통관, 납품 지속
C12: -. 1분기 운영 실적, 가 결산 진행중 | M12: -. 1분기 운영 실적 검토(중간점검)
M13: -. 2분기 운영 제품기획 협의 및 목표 수립 예정
C14: ▣ SECO창립티셔츠 제작
C15: -. 완제품 수입 통관 및 물류 입고 | M15: ▣ 도.도매(특정) 운영
C16: -. 품질 검사 및 주문처별 납품 완료 | M16: -. '제임스딘' 과 '돈앤돈스'의 카니발 현상 검토
M17: (남성용 32수 트렁크세트)
C18: ▣ 도.도매(특정) 운영
C19: -. 도.도매(특정) 운영 남성용 32수 트렁크세트, 초도분 납품 완료

Sheet PL_26 계획
A2: 과목 | B2: 합계 | C2: 2026년 1월 | D2: 2026년 2월 | E2: 2026년 3월 | F2: 2026년 4월 | G2: 2026년 5월 | H2: 2026년 6월 | I2: 2026년 7월 | J2: 2026년 8월 | K2: 2026년 9월 | L2: 2026년 10월 | M2: 2026년 11월 | N2: 2026년 12월 | P2: 당월 | Q2: 연간누계
A3: Ⅰ. 매 출 액 | B3: =SUM(C3:N3) -> 6795051033 | C3: =SUM(C4:C7) -> 284712111 | D3: =SUM(D4:D7) -> 507895922 | E3: =SUM(E4:E7) -> 500000000 | F3: =SUM(F4:F7) -> 628327000 | G3: =SUM(G4:G7) -> 630827000 | H3: =SUM(H4:H7) -> 630827000 | I3: =SUM(I4:I7) -> 558327000 | J3: =SUM(J4:J7) -> 340827000 | ... N3: =SUM(N4:N7) -> 651327000 | P3: =D3 -> 507895922 | Q3: =SUM(C3:N3) -> 6795051033 | R3: =Q3=B3 -> 1
A4: 상품(재고)매출 | B4: =SUM(C4:N4) -> 951064311 | C4: 284712111 | D4: 507895922 | E4: =-E12 -> 19742713 | F4: =-F12 -> 19742713 | G4: =-G12 -> 19742713 | H4: =-H12 -> 19742713 | I4: =-I12 -> 19742713 | J4: =-J12 -> 19742713 | K4: =-K12 -> 10000000 | L4: =-L12 -> 10000000 | ... N4: =-N12 -> 10000000 | P4: =D4 -> 507895922 | Q4: =SUM(C4:N4) -> 951064311 | R4: =Q4=B4 -> 1
A5: 아웃웨어매출 | B5: =SUM(C5:N5) -> 4194043722 | E5: =500000000-E4 -> 480257287 | F5: =505000000-F4 -> 485257287 | G5: =350000*1450-G4 -> 487757287 | H5: =350000*1450-H4 -> 487757287 | I5: =300000*1450-I4 -> 415257287 | J5: =150000*1450-J4 -> 197757287 | K5: =420000000-K4 -> 410000000 | L5: =420000000-L4 -> 410000000 | M5: =420000000-M4 -> 410000000 | N5: =420000000-N4 -> 410000000 | P5: =D5 -> 0 | Q5: =SUM(C5:N5) -> 4194043722 | R5: =Q5=B5 -> 1
